Workbook

Sheet IN1
AH1: VERSO MANAGEMENT | AR1: PARTNERS excluding JM | BB1: INTRODUCERS | BK1: JM
B2: Index | C2: Opportunity | D2: Sourcing Contract ref | E2: Cost per Share | F2: Investor Last Name | G2: Investor Middle Name | H2: Investor First Name | I2: Investor Entity | J2: Vehicle | K2: Gross Amount | L2: Amount invested | M2: Price per Share | N2: Number of shares invested | O2: Contract Date | P2: Spread PPS | Q2: Spread PPS Fees | R2: Subscription fees % | S2: Subscription fees | T2: Performance fees 1 | U2: Threshold 1 | V2: Performance fees 2 | W2: Threshold 2 | X2: Comments | Y2: TO DO | AC2: BD Fees % | AD2: BD fees | AE2: FINRA fees in share | AF2: FINRA fees | AH2: Subscription fees % | AI2: Subscription fees | AJ2: Performance fees 1 | AK2: Threshold 1 | AL2: Performance fees 2 | AM2: Threshold 2 | AN2: Spread PPS | AO2: Spread PPS Fees | AQ2: Name | AR2: Subscription fees % | AS2: Subscription fees | AT2: Performance fees 1 | AU2: Threshold 1 | AV2: Performance fees 2 | AW2: Threshold 2 | AX2: Spread PPS | AY2: Spread PPS Fees | BA2: Name | BB2: Subscription fees % | BC2: Subscription fees | BD2: Performance fees 1 | BE2: Threshold 1 | BF2: Performance fees 2 | BG2: Threshold 2 | BH2: Spread PPS | BI2: Spread PPS Fees | BK2: CHECK | BL2: CHECK
B3: 1 | C3: VEGINVEST | D3: VEG_VC6_TR8 | E3: 21 | I3: Innovatech 1 | J3: IN1 | K3: =914481.12 -> 914481.12 | L3: =K3 -> 914481.12 | M3: 23.52 | N3: =ROUNDDOWN('IN1'!$L3/'IN1'!$M3,0) -> 38881 | O3: 23/03/2021 | P3: 0 | Q3: =P3*'IN1'!$N3 -> 0 | R3: 0 | S3: =+'IN1'!$L3*'IN1'!$R3 -> 0 | T3: 0.2 | U3: 0x | X3: ISIN: CH0585378737 | AC3: 0 | AD3: =+AC3*'IN1'!$L3 -> 0 | AE3: 0 | AF3: =+AE3*'IN1'!$N3 -> 0 | AH3: 0 | AI3: =+AH3*'IN1'!$L3 -> 0 | AJ3: 0 | AK3: 0x | AN3: 0 | AO3: =+AN3*'IN1'!$N3 -> 0 | AR3: 0 | AS3: =+AR3*'IN1'!$L3 -> 0 | AT3: 0 | AU3: 0x | AX3: 0 | AY3: =+AX3*'IN1'!$N3 -> 0 | BB3: 0 | BC3: =+BB3*'IN1'!$L3 -> 0 | BD3: 0 | BE3: 0x | BH3: 0 | BI3: =+BH3*'IN1'!$N3 -> 0 | BK3: ='IN1'!$T3-AT3-BD3-AJ3 -> 0.2 | BL3: ='IN1'!$R3-AH3-AR3-BB3 -> 0
B4: 2 | C4: VEGINVEST | E4: 21 | J4: IN1 | K4: 0 | L4: 0 | M4: 23.52 | N4: =ROUNDDOWN('IN1'!$L4/'IN1'!$M4,0) -> 0 | P4: 0 | Q4: =P4*'IN1'!$N4 -> 0 | R4: 0 | S4: =+'IN1'!$L4*'IN1'!$R4 -> 0 | T4: 0 | U4: 0x | AC4: 0 | AD4: =+AC4*'IN1'!$L4 -> 0 | AE4: 0 | AF4: =+AE4*'IN1'!$N4 -> 0 | AH4: 0 | AI4: =+AH4*'IN1'!$L4 -> 0 | AJ4: 0 | AK4: 0x | AN4: 0 | AO4: =+AN4*'IN1'!$N4 -> 0 | AR4: 0 | AS4: =+AR4*'IN1'!$L4 -> 0 | AT4: 0 | AU4: 0x | AX4: 0 | AY4: =+AX4*'IN1'!$N4 -> 0 | BB4: 0 | BC4: =+BB4*'IN1'!$L4 -> 0 | BD4: 0 | BE4: 0x | BH4: 0 | BI4: =+BH4*'IN1'!$N4 -> 0 | BK4: ='IN1'!$T4-AT4-BD4-AJ4 -> 0 | BL4: ='IN1'!$R4-AH4-AR4-BB4 -> 0
C5: Total | K5: =SUBTOTAL(109,'IN1'!$K$3:$K$4) -> 914481.12 | L5: =SUBTOTAL(109,'IN1'!$L$3:$L$4) -> 914481.12 | N5: =SUBTOTAL(109,'IN1'!$N$3:$N$4) -> 38881 | Q5: =SUBTOTAL(109,'IN1'!$Q$3:$Q$4) -> 0 | S5: =SUBTOTAL(109,'IN1'!$S$3:$S$4) -> 0
K7: =+(Q7+S7)/'IN1'!$K$5 -> 0 | L7: =+(Q7+S7)/'IN1'!$L$5 -> 0 | Q7: =+SUM('IN1'!$Q$3:$Q$4)-SUM(AY3:AY4)-SUM(BI3:BJ4) -> 0 | S7: =+SUM('IN1'!$S$3:$S$4)-SUM(AS3:AS4)-SUM(BC3:BC4) -> 0 | T7: =SUMPRODUCT(T3:T4,L3:L4)/SUM(L3:L4) -> 0.2
Q8: =+Q7/'IN1'!$Q$5 -> #DIV/0! | S8: =+S7/'IN1'!$S$5 -> #DIV/0!

Sheet IN2
AI1: VERSO CAPITAL | AR1: PARTNERS excluding JM | BA1: INTRODUCERS | BJ1: JM
B2: Index | C2: Opportunity | D2: Sourcing Contract ref | E2: Cost per Share | F2: Investor Last Name | G2: Investor Middle Name | H2: Investor First Name | I2: Investor Entity | J2: Vehicle | K2: Amount invested | L2: Price per Share | M2: Number of shares invested | N2: Contract Date | O2: Spread PPS | P2: Spread PPS Fees | Q2: Subscription fees % | R2: Subscription fees | S2: Management Fee | T2: Performance fees 1 | U2: Threshold 1 | V2: Gross Div | W2: Net Div | X2: Perf Fee | Y2: Comments | Z2: TO DO | AD2: BD Fees % | AE2: BD fees | AF2: FINRA fees in share | AG2: FINRA fees | AI2: Subscription fees % | AJ2: Subscription fees | AK2: Performance fees 1 | AL2: Threshold 1 | AM2: Performance fees 2 | AN2: Threshold 2 | AO2: Spread PPS | AP2: Spread PPS Fees | AR2: Subscription fees % | AS2: Subscription fees | AT2: Performance fees 1 | AU2: Threshold 1 | AV2: Performance fees 2 | AW2: Threshold 2 | AX2: Spread PPS | AY2: Spread PPS Fees | BA2: Subscription fees % | BB2: Subscription fees | BC2: Performance fees 1 | BD2: Threshold 1 | BE2: Performance fees 2 | BF2: Threshold 2 | BG2: Spread PPS | BH2: Spread PPS Fees | BJ2: CHECK | BK2: CHECK
B3: 1 | C3: TECHMET | E3: 4139.39 | F3: HOLDEN | H3: David | J3: IN2 | K3: 500000 | L3: 4139.39 | M3: =ROUNDDOWN('IN2'!$K3/'IN2'!$L3,0) -> 120 | N3: 44407 | O3: 0 | P3: =O3*'IN2'!$M3 -> 0 | Q3: 0.03 | R3: =+'IN2'!$K3*'IN2'!$Q3 -> 15000 | S3: 0 | T3: 0.25 | U3: 0x | V3: =M3*529.9369 -> 63592.428 | W3: =M3*397.4526 -> 47694.312 | X3: 15898.1 | AD3: 0 | AE3: =+AD3*'IN2'!$K3 -> 0 | AF3: 0 | AG3: =+AF3*'IN2'!$M3 -> 0 | AI3: 0.01 | AJ3: =+AI3*'IN2'!$K3 -> 5000 | AK3: 0 | AL3: 0x | AM3: 0.0625 | AO3: 0 | AP3: =+AO3*'IN2'!$M3 -> 0 | AR3: 0.01 | AS3: =+AR3*'IN2'!$K3 -> 5000 | AT3: 0.0625 | AU3: 0x | AX3: 0 | AY3: =+AX3*'IN2'!$M3 -> 0 | BA3: 0.01 | BB3: =+BA3*'IN2'!$K3 -> 5000 | BC3: 0.125 | BD3: 0x | BG3: 0 | BH3: =+BG3*'IN2'!$M3 -> 0 | BJ3: ='IN2'!$T3-AT3-BC3-AK3 -> 0.0625 | BK3: ='IN2'!$Q3-AI3-AR3-BA3 -> 0
B4: 2 | C4: TECHMET | E4: 4139.39 | F4: ZORBAS | H4: Van | I4: 1982772 Ontario Ltd | J4: IN2 | K4: 500000 | L4: 4139.39 | M4: =ROUNDDOWN('IN2'!$K4/'IN2'!$L4,0) -> 120 | N4: 44407 | O4: 0 | P4: =O4*'IN2'!$M4 -> 0 | Q4: 0.03 | R4: =+'IN2'!$K4*'IN2'!$Q4 -> 15000 | S4: 0 | T4: 0.25 | U4: 0x | V4: =M4*529.9369 -> 63592.428 | W4: =M4*397.4526 -> 47694.312 | X4: 15898.1 | AD4: 0 | AE4: =+AD4*'IN2'!$K4 -> 0 | AF4: 0 | AG4: =+AF4*'IN2'!$M4 -> 0 | AI4: 0.01 | AJ4: =+AI4*'IN2'!$K4 -> 5000 | AK4: 0 | AL4: 0x | AM4: 0.0625 | AO4: 0 | AP4: =+AO4*'IN2'!$M4 -> 0 | AR4: 0.01 | AS4: =+AR4*'IN2'!$K4 -> 5000 | AT4: 0.0625 | AU4: 0x | AX4: 0 | AY4: =+AX4*'IN2'!$M4 -> 0 | BA4: 0.01 | BB4: =+BA4*'IN2'!$K4 -> 5000 | BC4: 0.125 | BD4: 0x | BG4: 0 | BH4: =+BG4*'IN2'!$M4 -> 0 | BJ4: ='IN2'!$T4-AT4-BC4-AK4 -> 0.0625 | BK4: ='IN2'!$Q4-AI4-AR4-BA4 -> 0
B5: 3 | C5: TECHMET | E5: 4139.39 | F5: NOCCIOLINO | H5: Albert | J5: IN2 | K5: 500000 | L5: 4139.39 | M5: =ROUNDDOWN('IN2'!$K5/'IN2'!$L5,0) -> 120 | N5: 44407 | O5: 0 | P5: =O5*'IN2'!$M5 -> 0 | Q5: 0.03 | R5: =+'IN2'!$K5*'IN2'!$Q5 -> 15000 | S5: 0 | T5: 0.25 | U5: 0x | V5: =M5*529.9369 -> 63592.428 | W5: =M5*397.4526 -> 47694.312 | X5: 15898.1 | AD5: 0 | AE5: =+AD5*'IN2'!$K5 -> 0 | AF5: 0 | AG5: =+AF5*'IN2'!$M5 -> 0 | AI5: 0.01 | AJ5: =+AI5*'IN2'!$K5 -> 5000 | AK5: 0 | AL5: 0x | AM5: 0.0625 | AO5: 0 | AP5: =+AO5*'IN2'!$M5 -> 0 | AR5: 0.01 | AS5: =+AR5*'IN2'!$K5 -> 5000 | AT5: 0.0625 | AU5: 0x | AX5: 0 | AY5: =+AX5*'IN2'!$M5 -> 0 | BA5: 0.01 | BB5: =+BA5*'IN2'!$K5 -> 5000 | BC5: 0.125 | BD5: 0x | BG5: 0 | BH5: =+BG5*'IN2'!$M5 -> 0 | BJ5: ='IN2'!$T5-AT5-BC5-AK5 -> 0.0625 | BK5: ='IN2'!$Q5-AI5-AR5-BA5 -> 0
B6: 4 | C6: TECHMET | E6: 4139.39 | F6: PAULSEN | G6: Alan | H6: Christopher | J6: IN2 | K6: 500000 | L6: 4139.39 | M6: =ROUNDDOWN('IN2'!$K6/'IN2'!$L6,0) -> 120 | N6: 44407 | O6: 0 | P6: =O6*'IN2'!$M6 -> 0 | Q6: 0.03 | R6: =+'IN2'!$K6*'IN2'!$Q6 -> 15000 | S6: 0 | T6: 0.25 | U6: 0x | V6: =M6*529.9369 -> 63592.428 | W6: =M6*397.4526 -> 47694.312 | X6: 15898.1 | AD6: 0 | AE6: =+AD6*'IN2'!$K6 -> 0 | AF6: 0 | AG6: =+AF6*'IN2'!$M6 -> 0 | AI6: 0.01 | AJ6: =+AI6*'IN2'!$K6 -> 5000 | AK6: 0 | AL6: 0x | AM6: 0.0625 | AO6: 0 | AP6: =+AO6*'IN2'!$M6 -> 0 | AR6: 0.01 | AS6: =+AR6*'IN2'!$K6 -> 5000 | AT6: 0.0625 | AU6: 0x | AX6: 0 | AY6: =+AX6*'IN2'!$M6 -> 0 | BA6: 0.01 | BB6: =+BA6*'IN2'!$K6 -> 5000 | BC6: 0.125 | BD6: 0x | BG6: 0 | BH6: =+BG6*'IN2'!$M6 -> 0 | BJ6: ='IN2'!$T6-AT6-BC6-AK6 -> 0.0625 | BK6: ='IN2'!$Q6-AI6-AR6-BA6 -> 0
B7: 6 | C7: TECHMET | E7: 4139.39 | F7: HALL | G7: David | H7: Gary | J7: IN2 | K7: 200000 | L7: 4139.39 | M7: =ROUNDDOWN('IN2'!$K7/'IN2'!$L7,0) -> 48 | N7: 44407 | O7: 0 | P7: =O7*'IN2'!$M7 -> 0 | Q7: 0.03 | R7: =+'IN2'!$K7*'IN2'!$Q7 -> 6000 | S7: 0 | T7: 0.25 | U7: 0x | V7: =M7*529.9369 -> 25436.971 | W7: =M7*397.4526 -> 19077.725 | X7: 6359.24 | AD7: 0 | AE7: =+AD7*'IN2'!$K7 -> 0 | AF7: 0 | AG7: =+AF7*'IN2'!$M7 -> 0 | AI7: 0.01 | AJ7: =+AI7*'IN2'!$K7 -> 2000 | AK7: 0 | AL7: 0x | AM7: 0.0625 | AO7: 0 | AP7: =+AO7*'IN2'!$M7 -> 0 | AR7: 0.01 | AS7: =+AR7*'IN2'!$K7 -> 2000 | AT7: 0.0625 | AU7: 0x | AX7: 0 | AY7: =+AX7*'IN2'!$M7 -> 0 | BA7: 0.01 | BB7: =+BA7*'IN2'!$K7 -> 2000 | BC7: 0.125 | BD7: 0x | BG7: 0 | BH7: =+BG7*'IN2'!$M7 -> 0 | BJ7: ='IN2'!$T7-AT7-BC7-AK7 -> 0.0625 | BK7: ='IN2'!$Q7-AI7-AR7-BA7 -> 0
B8: 8 | C8: TECHMET | E8: 4139.39 | F8: BAUMSLAG | H8: Dan | J8: IN2 | K8: 4139.39 | L8: 4139.39 | M8: =ROUNDDOWN('IN2'!$K8/'IN2'!$L8,0) -> 1 | N8: 44407 | O8: 0 | P8: =O8*'IN2'!$M8 -> 0 | Q8: 0 | R8: =+'IN2'!$K8*'IN2'!$Q8 -> 0 | S8: 0 | T8: 0 | U8: 0x | V8: =M8*529.9369 -> 529.9369 | AD8: 0 | AE8: =+AD8*'IN2'!$K8 -> 0 | AF8: 0 | AG8: =+AF8*'IN2'!$M8 -> 0 | AI8: 0 | AJ8: =+AI8*'IN2'!$K8 -> 0 | AK8: 0 | AL8: 0x | AM8: 0 | AO8: 0 | AP8: =+AO8*'IN2'!$M8 -> 0 | AR8: 0 | AS8: =+AR8*'IN2'!$K8 -> 0 | AT8: 0 | AU8: 0x | AX8: 0 | AY8: =+AX8*'IN2'!$M8 -> 0 | BA8: 0 | BB8: =+BA8*'IN2'!$K8 -> 0 | BC8: 0 | BD8: 0x | BG8: 0 | BH8: =+BG8*'IN2'!$M8 -> 0 | BJ8: ='IN2'!$T8-AT8-BC8-AK8 -> 0 | BK8: ='IN2'!$Q8-AI8-AR8-BA8 -> 0
B9: 9 | C9: TECHMET | E9: 4139.39 | F9: MACHOT | H9: Julien | J9: IN2 | K9: 12418.17 | L9: 4139.39 | M9: =ROUNDDOWN('IN2'!$K9/'IN2'!$L9,0) -> 3 | N9: 44407 | O9: 0 | P9: =O9*'IN2'!$M9 -> 0 | Q9: 0 | R9: =+'IN2'!$K9*'IN2'!$Q9 -> 0 | S9: 0 | T9: 0 | U9: 0x | V9: =M9*529.9369 -> 1589.8107 | AD9: 0 | AE9: =+AD9*'IN2'!$K9 -> 0 | AF9: 0 | AG9: =+AF9*'IN2'!$M9 -> 0 | AI9: 0 | AJ9: =+AI9*'IN2'!$K9 -> 0 | AK9: 0 | AL9: 0x | AM9: 0 | AO9: 0 | AP9: =+AO9*'IN2'!$M9 -> 0 | AR9: 0 | AS9: =+AR9*'IN2'!$K9 -> 0 | AT9: 0 | AU9: 0x | AX9: 0 | AY9: =+AX9*'IN2'!$M9 -> 0 | BA9: 0 | BB9: =+BA9*'IN2'!$K9 -> 0 | BC9: 0 | BD9: 0x | BG9: 0 | BH9: =+BG9*'IN2'!$M9 -> 0 | BJ9: ='IN2'!$T9-AT9-BC9-AK9 -> 0 | BK9: ='IN2'!$Q9-AI9-AR9-BA9 -> 0
B10: 10 | C10: TECHMET | E10: 4139.39 | F10: JONES | G10: Lee | H10: Benjamin | J10: IN2 | K10: 296051.66 | L10: 4139.39 | M10: =ROUNDDOWN('IN2'!$K10/'IN2'!$L10,0) -> 71 | N10: 44425 | O10: 0 | P10: =O10*'IN2'!$M10 -> 0 | Q10: 0.03 | R10: =+'IN2'!$K10*'IN2'!$Q10 -> 8881.5498 | S10: 0 | T10: 0.25 | U10: 0x | V10: =M10*529.9369 -> 37625.52 | W10: =M10*397.4526 -> 28219.135 | X10: 9406.38 | AD10: 0 | AE10: =+AD10*'IN2'!$K10 -> 0 | AF10: 0 | AG10: =+AF10*'IN2'!$M10 -> 0 | AI10: 0.01 | AJ10: =+AI10*'IN2'!$K10 -> 2960.5166 | AK10: 0 | AL10: 0x | AM10: 0.0625 | AO10: 0 | AP10: =+AO10*'IN2'!$M10 -> 0 | AR10: 0.01 | AS10: =+AR10*'IN2'!$K10 -> 2960.5166 | AT10: 0.0625 | AU10: 0x | AX10: 0 | AY10: =+AX10*'IN2'!$M10 -> 0 | BA10: 0.01 | BB10: =+BA10*'IN2'!$K10 -> 2960.5166 | BC10: 0.125 | BD10: 0x | BG10: 0 | BH10: =+BG10*'IN2'!$M10 -> 0 | BJ10: ='IN2'!$T10-AT10-BC10-AK10 -> 0.0625 | BK10: ='IN2'!$Q10-AI10-AR10-BA10 -> 0
B11: 11 | C11: TECHMET | E11: 4139.39 | J11: IN2 | K11: 0 | L11: 4139.39 | M11: =ROUNDDOWN('IN2'!$K11/'IN2'!$L11,0) -> 0 | O11: 0 | P11: =O11*'IN2'!$M11 -> 0 | Q11: 0 | R11: =+'IN2'!$K11*'IN2'!$Q11 -> 0 | S11: 0 | T11: 0 | U11: 0x | V11: =M11*529.9369 -> 0 | W11: =M11*397.4526 -> 0 | X11: =V11-W11 -> 0 | AD11: 0 | AE11: =+AD11*'IN2'!$K11 -> 0 | AF11: 0 | AG11: =+AF11*'IN2'!$M11 -> 0 | AI11: 0 | AJ11: =+AI11*'IN2'!$K11 -> 0 | AK11: 0 | AL11: 0x | AM11: 0 | AO11: 0 | AP11: =+AO11*'IN2'!$M11 -> 0 | AR11: 0 | AS11: =+AR11*'IN2'!$K11 -> 0 | AT11: 0 | AU11: 0x | AX11: 0 | AY11: =+AX11*'IN2'!$M11 -> 0 | BA11: 0 | BB11: =+BA11*'IN2'!$K11 -> 0 | BC11: 0 | BD11: 0x | BG11: 0 | BH11: =+BG11*'IN2'!$M11 -> 0 | BJ11: ='IN2'!$T11-AT11-BC11-AK11 -> 0 | BK11: ='IN2'!$Q11-AI11-AR11-BA11 -> 0
C12: Total | K12: =SUBTOTAL(109,'IN2'!$K$3:$K$11) -> 2512609.2 | M12: =SUBTOTAL(109,'IN2'!$M$3:$M$11) -> 603 | P12: =SUBTOTAL(109,'IN2'!$P$3:$P$11) -> 0 | R12: =SUBTOTAL(109,'IN2'!$R$3:$R$11) -> 74881.55 | X12: =V12-W12 -> 0
K14: =+(P14+R14)/'IN2'!$K$12 -> 0.0099341021 | P14: =+SUM('IN2'!$P$3:$P$11)-SUM(AY3:AY11)-SUM(BH3:BI11) -> 0 | R14: =+SUM('IN2'!$R$3:$R$11)-SUM(AS3:AS11)-SUM(BB3:BB11) -> 24960.517 | T14: =SUMPRODUCT(T3:T11,K3:K11)/SUM(K3:K11) -> 0.24835255 | V14: =sum(V3:V11) -> 319551.95 | W14: =sum(W3:W11) -> 238074.11 | X14: 79358.04
P15: =+P14/'IN2'!$P$12 -> #DIV/0! | R15: =+R14/'IN2'!$R$12 -> 0.33333333
U18: gross dividend | V18: 319590 | W18: in USD
U19: bank fee | V19: 38 | W19: in USD
U20: net dividend | V20: =V18-V19 -> 319552 | W20: in USD
U21: perf fee | V21: 529.9369 | W21: in USD
U22: John's Group | V22: 599 | W22: in share count
U23: John's USD | V23: =V22*V21 -> 317432.2
U24: 25% perf | V24: =V21*25% -> 132.48423
U25: net perf | V25: =V21-V24 -> 397.45267
U26: payout total | V26: 238074.19
U27: total fees | V27: 79358.062 | W27: (out of which 50% for John Moore)

Sheet IN3
AJ1: VERSO CAPITAL | AT1: PARTNERS excluding JM | BD1: INTRODUCERS | BM1: JM
B2: Index | C2: Opportunity | D2: Sourcing Contract ref | E2: Cost per Share | F2: Cerificates | G2: Investor Last Name | H2: Investor Middle Name | I2: Investor First Name | J2: Investor Entity | K2: Vehicle | L2: Amount invested | M2: Price per Share | N2: Number of shares invested | O2: Position | P2: Contract Date | Q2: Spread PPS | R2: Spread PPS Fees | S2: Subscription fees % | T2: Subscription fees | U2: Management Fee | V2: Performance fees 1 | W2: Threshold 1 | X2: Performance fees 2 | Y2: Threshold 2 | Z2: Comments | AA2: TO DO | AE2: BD Fees % | AF2: BD fees | AG2: FINRA fees in share | AH2: FINRA fees | AJ2: Subscription fees % | AK2: Subscription fees | AL2: Performance fees 1 | AM2: Threshold 1 | AN2: Performance fees 2 | AO2: Threshold 2 | AP2: Spread PPS | AQ2: Spread PPS Fees | AS2: Name | AT2: Subscription fees % | AU2: Subscription fees | AV2: Performance fees 1 | AW2: Threshold 1 | AX2: Performance fees 2 | AY2: Threshold 2 | AZ2: Spread PPS | BA2: Spread PPS Fees | BC2: Name | BD2: Subscription fees % | BE2: Subscription fees | BF2: Performance fees 1 | BG2: Threshold 1 | BH2: Performance fees 2 | BI2: Threshold 2 | BJ2: Spread PPS | BK2: Spread PPS Fees | BM2: CHECK | BN2: CHECK
B3: 1 | C3: SC CO INVEST 1 | D3: Series C Preferred | E3: 4.1359 | F3: IN3F001 | J3: Zandera (Holdco) Limited | K3: IN3 | L3: 500000 | M3: 8.2718 | N3: 60446 | O3: 0 | P3: 24/01/2022 | Q3: =M3-E3 -> 4.1359 | R3: =Q3*'IN3'!$N3 -> 249998.61 | S3: 0.04 | T3: =+'IN3'!$L3*'IN3'!$S3 -> 20000 | U3: 0 | V3: 0.2 | W3: 0x | AE3: 0 | AF3: =+AE3*'IN3'!$L3 -> 0 | AG3: 0 | AH3: =+AG3*'IN3'!$N3 -> 0 | AJ3: 0 | AK3: =+AJ3*'IN3'!$L3 -> 0 | AL3: 0 | AM3: 0x | AP3: 0 | AQ3: =+AP3*'IN3'!$N3 -> 0 | AS3: Anand | AT3: 0.01 | AU3: =+AT3*'IN3'!$L3 -> 5000 | AV3: 0.085 | AW3: 0x | AZ3: =Q3-AP3-BJ3 -> 1.24077 | BA3: =+AZ3*'IN3'!$N3 -> 74999.583 | BC3: Altras+Andrew | BD3: =2%+1% -> 0.03 | BE3: =+BD3*'IN3'!$L3 -> 15000 | BF3: 0 | BG3: 0x | BJ3: 2.89513 | BK3: =+BJ3*'IN3'!$N3 -> 174999.03 | BM3: ='IN3'!$V3-AV3-BF3-AL3 -> 0.115 | BN3: ='IN3'!$S3-AJ3-AT3-BD3 -> 0
B4: 2 | C4: SC CO INVEST 1 | D4: Series C Preferred | E4: 4.1359 | F4: IN3F002 | J4: Wymo Finance Limited | K4: IN3 | L4: 500000 | M4: 4.1359 | N4: 120892 | O4: 0 | P4: 24/01/2022 | Q4: =M4-E4 -> 0 | R4: =Q4*'IN3'!$N4 -> 0 | S4: 0.02 | T4: =+'IN3'!$L4*'IN3'!$S4 -> 10000 | U4: 0 | V4: 0.2 | W4: 0x | Z4: Transfer to mahesh | AE4: 0 | AF4: =+AE4*'IN3'!$L4 -> 0 | AG4: 0 | AH4: =+AG4*'IN3'!$N4 -> 0 | AJ4: 0 | AK4: =+AJ4*'IN3'!$L4 -> 0 | AL4: 0 | AM4: 0x | AP4: 0 | AQ4: =+AP4*'IN3'!$N4 -> 0 | AS4: Anand | AT4: 0.01 | AU4: =+AT4*'IN3'!$L4 -> 5000 | AV4: 0.085 | AW4: 0x | AZ4: 0 | BA4: =+AZ4*'IN3'!$N4 -> 0 | BC4: Andrew | BD4: 0.01 | BE4: =+BD4*'IN3'!$L4 -> 5000 | BF4: 0 | BG4: 0x | BJ4: 0 | BK4: =+BJ4*'IN3'!$N4 -> 0 | BM4: ='IN3'!$V4-AV4-BF4-AL4 -> 0.115 | BN4: ='IN3'!$S4-AJ4-AT4-BD4 -> 0
B5: 3 | C5: SC CO INVEST 1 | D5: Series C Preferred | E5: 4.1359 | F5: IN3F003 | J5: HASSBRO Investments Limited | K5: IN3 | L5: 500000 | M5: 4.1359 | N5: 120892 | O5: =N5 -> 120892 | P5: 24/01/2022 | Q5: =M5-E5 -> 0 | R5: =Q5*'IN3'!$N5 -> 0 | S5: 0.02 | T5: =+'IN3'!$L5*'IN3'!$S5 -> 10000 | U5: 0 | V5: 0.2 | W5: 0x | AE5: 0 | AF5: =+AE5*'IN3'!$L5 -> 0 | AG5: 0 | AH5: =+AG5*'IN3'!$N5 -> 0 | AJ5: 0 | AK5: =+AJ5*'IN3'!$L5 -> 0 | AL5: 0 | AM5: 0x | AP5: 0 | AQ5: =+AP5*'IN3'!$N5 -> 0 | AS5: Anand | AT5: 0.01 | AU5: =+AT5*'IN3'!$L5 -> 5000 | AV5: 0.085 | AW5: 0x | AZ5: 0 | BA5: =+AZ5*'IN3'!$N5 -> 0 | BC5: Andrew | BD5: 0.01 | BE5: =+BD5*'IN3'!$L5 -> 5000 | BF5: 0 | BG5: 0x | BJ5: 0 | BK5: =+BJ5*'IN3'!$N5 -> 0 | BM5: ='IN3'!$V5-AV5-BF5-AL5 -> 0.115 | BN5: ='IN3'!$S5-AJ5-AT5-BD5 -> 0
B6: 6 | C6: SC CO INVEST 1 | D6: Series C Preferred | E6: 4.1359 | F6: IN3F004 | J6: N SQUARE PATEL LLC | K6: IN3 | L6: 100000 | M6: 4.1359 | N6: 24178 | O6: =N6 -> 24178 | P6: 27/01/2022 | Q6: =M6-E6 -> 0 | R6: =Q6*'IN3'!$N6 -> 0 | S6: 0.02 | T6: =+'IN3'!$L6*'IN3'!$S6 -> 2000 | U6: 0 | V6: 0.2 | W6: 0x | AE6: 0.02 | AF6: =+AE6*'IN3'!$L6 -> 2000 | AG6: 0 | AH6: =+AG6*'IN3'!$N6 -> 0 | AJ6: 0 | AK6: =+AJ6*'IN3'!$L6 -> 0 | AL6: 0 | AM6: 0x | AP6: 0 | AQ6: =+AP6*'IN3'!$N6 -> 0 | AS6: Anand | AT6: 0.01 | AU6: =+AT6*'IN3'!$L6 -> 1000 | AV6: 0.085 | AW6: 0x | AZ6: 0 | BA6: =+AZ6*'IN3'!$N6 -> 0 | BC6: Andrew | BD6: 0.01 | BE6: =+BD6*'IN3'!$L6 -> 1000 | BF6: 0 | BG6: 0x | BJ6: 0 | BK6: =+BJ6*'IN3'!$N6 -> 0 | BM6: ='IN3'!$V6-AV6-BF6-AL6 -> 0.115 | BN6: ='IN3'!$S6-AJ6-AT6-BD6 -> 0
B7: 8 | C7: SC CO INVEST 1 | D7: Series C Preferred | E7: 4.1359 | F7: IN3F005 | G7: GRACE | I7: Elizabeth | K7: IN3 | L7: 50000 | M7: 4.1359 | N7: 12089 | O7: =N7 -> 12089 | P7: 27/01/2022 | Q7: =M7-E7 -> 0 | R7: =Q7*'IN3'!$N7 -> 0 | S7: 0.02 | T7: =+'IN3'!$L7*'IN3'!$S7 -> 1000 | U7: 0 | V7: 0.2 | W7: 0x | AE7: 0.02 | AF7: =+AE7*'IN3'!$L7 -> 1000 | AG7: 0 | AH7: =+AG7*'IN3'!$N7 -> 0 | AJ7: 0 | AK7: =+AJ7*'IN3'!$L7 -> 0 | AL7: 0 | AM7: 0x | AP7: 0 | AQ7: =+AP7*'IN3'!$N7 -> 0 | AS7: Anand | AT7: 0.01 | AU7: =+AT7*'IN3'!$L7 -> 500 | AV7: 0.085 | AW7: 0x | AZ7: 0 | BA7: =+AZ7*'IN3'!$N7 -> 0 | BC7: Andrew | BD7: 0.01 | BE7: =+BD7*'IN3'!$L7 -> 500 | BF7: 0 | BG7: 0x | BJ7: 0 | BK7: =+BJ7*'IN3'!$N7 -> 0 | BM7: ='IN3'!$V7-AV7-BF7-AL7 -> 0.115 | BN7: ='IN3'!$S7-AJ7-AT7-BD7 -> 0
B8: 9 | C8: SC CO INVEST 1 | D8: Series C Preferred | E8: 4.1359 | F8: IN3F006 | G8: GRACE | I8: John | J8: Sherri Lipton Grace 2020 Irrevocable Family Trust | K8: IN3 | L8: 50000 | M8: 4.1359 | N8: 12089 | O8: =N8 -> 12089 | P8: 27/01/2022 | Q8: =M8-E8 -> 0 | R8: =Q8*'IN3'!$N8 -> 0 | S8: 0.02 | T8: =+'IN3'!$L8*'IN3'!$S8 -> 1000 | U8: 0 | V8: 0.2 | W8: 0x | AE8: 0.02 | AF8: =+AE8*'IN3'!$L8 -> 1000 | AG8: 0 | AH8: =+AG8*'IN3'!$N8 -> 0 | AJ8: 0 | AK8: =+AJ8*'IN3'!$L8 -> 0 | AL8: 0 | AM8: 0x | AP8: 0 | AQ8: =+AP8*'IN3'!$N8 -> 0 | AS8: Anand | AT8: 0.01 | AU8: =+AT8*'IN3'!$L8 -> 500 | AV8: 0.085 | AW8: 0x | AZ8: 0 | BA8: =+AZ8*'IN3'!$N8 -> 0 | BC8: Andrew | BD8: 0.01 | BE8: =+BD8*'IN3'!$L8 -> 500 | BF8: 0 | BG8: 0x | BJ8: 0 | BK8: =+BJ8*'IN3'!$N8 -> 0 | BM8: ='IN3'!$V8-AV8-BF8-AL8 -> 0.115 | BN8: ='IN3'!$S8-AJ8-AT8-BD8 -> 0
B9: 10 | C9: SC CO INVEST 1 | D9: Series C Preferred | E9: 4.1359 | F9: IN3F007 | J9: Zandera (Holdco) Limited | K9: IN3 | L9: 500000 | M9: 8.2718 | N9: 60446 | O9: 0 | P9: 24/02/2022 | Q9: =M9-E9 -> 4.1359 | R9: =Q9*'IN3'!$N9 -> 249998.61 | S9: 0.04 | T9: =+'IN3'!$L9*'IN3'!$S9 -> 20000 | U9: 0 | V9: 0.2 | W9: 0x | AE9: 0 | AF9: =+AE9*'IN3'!$L9 -> 0 | AG9: 0 | AH9: =+AG9*'IN3'!$N9 -> 0 | AJ9: 0 | AK9: =+AJ9*'IN3'!$L9 -> 0 | AL9: 0 | AM9: 0x | AP9: 0 | AQ9: =+AP9*'IN3'!$N9 -> 0 | AS9: Anand | AT9: 0.01 | AU9: =+AT9*'IN3'!$L9 -> 5000 | AV9: 0.085 | AW9: 0x | AZ9: =Q9-AP9-BJ9 -> 1.24077 | BA9: =+AZ9*'IN3'!$N9 -> 74999.583 | BC9: Altras+Andrew | BD9: =2%+1% -> 0.03 | BE9: =+BD9*'IN3'!$L9 -> 15000 | BF9: 0 | BG9: 0x | BJ9: 2.89513 | BK9: =+BJ9*'IN3'!$N9 -> 174999.03 | BM9: ='IN3'!$V9-AV9-BF9-AL9 -> 0.115 | BN9: ='IN3'!$S9-AJ9-AT9-BD9 -> 0
B10: 11 | C10: SC CO INVEST 1 | D10: Series C Preferred | E10: 4.1359 | F10: IN3F008 | G10: LOWY | I10: Jeremy | K10: IN3 | L10: 50000 | M10: 4.1359 | N10: 12089 | O10: =N10 -> 12089 | P10: 27/01/2022 | Q10: =M10-E10 -> 0 | R10: =Q10*'IN3'!$N10 -> 0 | S10: 0.02 | T10: =+'IN3'!$L10*'IN3'!$S10 -> 1000 | U10: 0 | V10: 0.2 | W10: 0x | AE10: 0.02 | AF10: =+AE10*'IN3'!$L10 -> 1000 | AG10: 0 | AH10: =+AG10*'IN3'!$N10 -> 0 | AJ10: 0 | AK10: =+AJ10*'IN3'!$L10 -> 0 | AL10: 0 | AM10: 0x | AP10: 0 | AQ10: =+AP10*'IN3'!$N10 -> 0 | AS10: Anand | AT10: 0.01 | AU10: =+AT10*'IN3'!$L10 -> 500 | AV10: 0.085 | AW10: 0x | AZ10: 0 | BA10: =+AZ10*'IN3'!$N10 -> 0 | BC10: Andrew | BD10: 0.01 | BE10: =+BD10*'IN3'!$L10 -> 500 | BF10: 0 | BG10: 0x | BJ10: 0 | BK10: =+BJ10*'IN3'!$N10 -> 0 | BM10: ='IN3'!$V10-AV10-BF10-AL10 -> 0.115 | BN10: ='IN3'!$S10-AJ10-AT10-BD10 -> 0
B11: 12 | C11: SC CO INVEST 1 | D11: Zandera | E11: =M3 -> 8.2718 | F11: IN3F009 | G11: RYAN | I11: Michael | K11: IN3 | L11: 500000 | M11: 8.2718 | N11: 60446 | O11: =N11 -> 60446 | P11: 45661 | Q11: =M11-E11 -> 0 | R11: =Q11*'IN3'!$N11 -> 0 | S11: 0 | T11: =+'IN3'!$L11*'IN3'!$S11 -> 0 | U11: 0 | V11: 0.2 | W11: 0x
B12: 13 | C12: SC CO INVEST 1 | D12: Zandera | E12: =M9 -> 8.2718 | F12: IN3F010 | G12: RYAN | I12: Michael | K12: IN3 | L12: 500000 | M12: 8.2718 | N12: 60446 | O12: =N12 -> 60446 | P12: 45661 | Q12: =M12-E12 -> 0 | R12: =Q12*'IN3'!$N12 -> 0 | S12: 0 | T12: =+'IN3'!$L12*'IN3'!$S12 -> 0 | U12: 0 | V12: 0.2 | W12: 0x
C13: Total | L13: =SUBTOTAL(109,'IN3'!$L$3:$L$10) -> 2250000 | N13: =SUBTOTAL(109,'IN3'!$N$3:$N$12) -> 544013 | O13: =SUBTOTAL(109,'IN3'!$O$3:$O$12) -> 302229 | R13: =SUBTOTAL(109,'IN3'!$R$3:$R$10) -> 499997.22 | T13: =SUBTOTAL(109,'IN3'!$T$3:$T$10) -> 65000
L15: =+(R15+T15)/'IN3'!$L$13 -> -0.0022222222 | R15: =+SUM('IN3'!$R$3:$R$10)-SUM(BA3:BA10)-SUM(BK3:BL10) -> 0 | T15: =+SUM('IN3'!$T$3:$T$10)-SUM(AU3:AU10)-SUM(BE3:BE10)-SUM(AF3:AF10) -> -5000 | V15: =SUMPRODUCT(V3:V10,L3:L10)/SUM(L3:L10) -> 0.2
R16: =+R15/'IN3'!$R$13 -> 0 | T16: =+T15/'IN3'!$T$13 -> -0.076923077

Sheet IN4
AH1: VERSO CAPITAL | AR1: PARTNERS excluding JM | BB1: INTRODUCERS | BK1: JM
B2: Index | C2: Opportunity | D2: Sourcing Contract ref | E2: Cost per Share | F2: Investor Last Name | G2: Investor Middle Name | H2: Investor First Name | I2: Investor Entity | J2: Vehicle | K2: Amount invested | L2: Price per Share | M2: Number of shares invested | N2: Contract Date | O2: Spread PPS | P2: Spread PPS Fees | Q2: Subscription fees % | R2: Subscription fees | S2: Management Fee | T2: Performance fees 1 | U2: Threshold 1 | V2: Performance fees 2 | W2: Threshold 2 | X2: Comments | Y2: TO DO | AC2: BD Fees % | AD2: BD fees | AE2: FINRA fees in share | AF2: FINRA fees | AH2: Subscription fees % | AI2: Subscription fees | AJ2: Performance fees 1 | AK2: Threshold 1 | AL2: Performance fees 2 | AM2: Threshold 2 | AN2: Spread PPS | AO2: Spread PPS Fees | AQ2: Name | AR2: Subscription fees % | AS2: Subscription fees | AT2: Performance fees 1 | AU2: Threshold 1 | AV2: Performance fees 2 | AW2: Threshold 2 | AX2: Spread PPS | AY2: Spread PPS Fees | BA2: Name | BB2: Subscription fees % | BC2: Subscription fees | BD2: Performance fees 1 | BE2: Threshold 1 | BF2: Performance fees 2 | BG2: Threshold 2 | BH2: Spread PPS | BI2: Spread PPS Fees | BK2: CHECK | BL2: CHECK
B3: 1 | C3: IFLIV ACQUISITION | E3: 1e-05 | I3: VERSO HOLDINGS SARL | J3: IN4 | K3: =L3*M3 -> 1.5 | L3: 1e-05 | M3: 150000 | N3: 16/06/2022 | O3: =L3-E3 -> 0 | P3: =O3*'IN4'!$M3 -> 0 | Q3: 0 | R3: =+'IN4'!$K3*'IN4'!$Q3 -> 0 | S3: 0 | T3: 0 | U3: 0x | AC3: 0 | AD3: =+AC3*'IN4'!$K3 -> 0 | AE3: 0 | AF3: =+AE3*'IN4'!$M3 -> 0 | AH3: 0 | AI3: =+AH3*'IN4'!$K3 -> 0 | AJ3: 0 | AK3: 0x | AN3: 0 | AO3: =+AN3*'IN4'!$M3 -> 0 | AR3: 0 | AS3: =+AR3*'IN4'!$K3 -> 0 | AT3: 0 | AU3: 0x | AX3: 0 | AY3: =+AX3*'IN4'!$M3 -> 0 | BB3: 0 | BC3: =+BB3*'IN4'!$K3 -> 0 | BD3: 0 | BE3: 0x | BH3: 0 | BI3: =+BH3*'IN4'!$M3 -> 0 | BK3: ='IN4'!$T3-AT3-BD3-AJ3 -> 0 | BL3: ='IN4'!$Q3-AH3-AR3-BB3 -> 0
B4: 2 | C4: IFLIV ACQUISITION | E4: 1e-05 | J4: IN4 | K4: 0 | L4: 1e-05 | M4: 0 | O4: =L4-E4 -> 0 | P4: =O4*'IN4'!$M4 -> 0 | Q4: 0 | R4: =+'IN4'!$K4*'IN4'!$Q4 -> 0 | S4: 0 | T4: 0 | U4: 0x | AC4: 0 | AD4: =+AC4*'IN4'!$K4 -> 0 | AE4: 0 | AF4: =+AE4*'IN4'!$M4 -> 0 | AH4: 0 | AI4: =+AH4*'IN4'!$K4 -> 0 | AJ4: 0 | AK4: 0x | AN4: 0 | AO4: =+AN4*'IN4'!$M4 -> 0 | AR4: 0 | AS4: =+AR4*'IN4'!$K4 -> 0 | AT4: 0 | AU4: 0x | AX4: 0 | AY4: =+AX4*'IN4'!$M4 -> 0 | BB4: 0 | BC4: =+BB4*'IN4'!$K4 -> 0 | BD4: 0 | BE4: 0x | BH4: 0 | BI4: =+BH4*'IN4'!$M4 -> 0 | BK4: ='IN4'!$T4-AT4-BD4-AJ4 -> 0 | BL4: ='IN4'!$Q4-AH4-AR4-BB4 -> 0
B5: 3 | C5: IFLIV ACQUISITION | E5: 1e-05 | J5: IN4 | K5: 0 | L5: 1e-05 | M5: 0 | O5: =L5-E5 -> 0 | P5: =O5*'IN4'!$M5 -> 0 | Q5: 0 | R5: =+'IN4'!$K5*'IN4'!$Q5 -> 0 | S5: 0 | T5: 0 | U5: 0x | AC5: 0 | AD5: =+AC5*'IN4'!$K5 -> 0 | AE5: 0 | AF5: =+AE5*'IN4'!$M5 -> 0 | AH5: 0 | AI5: =+AH5*'IN4'!$K5 -> 0 | AJ5: 0 | AK5: 0x | AN5: 0 | AO5: =+AN5*'IN4'!$M5 -> 0 | AR5: 0 | AS5: =+AR5*'IN4'!$K5 -> 0 | AT5: 0 | AU5: 0x | AX5: 0 | AY5: =+AX5*'IN4'!$M5 -> 0 | BB5: 0 | BC5: =+BB5*'IN4'!$K5 -> 0 | BD5: 0 | BE5: 0x | BH5: 0 | BI5: =+BH5*'IN4'!$M5 -> 0 | BK5: ='IN4'!$T5-AT5-BD5-AJ5 -> 0 | BL5: ='IN4'!$Q5-AH5-AR5-BB5 -> 0
C6: Total | K6: =SUBTOTAL(109,'IN4'!$K$3:$K$5) -> 1.5 | M6: =SUBTOTAL(109,'IN4'!$M$3:$M$5) -> 150000 | P6: =SUBTOTAL(109,'IN4'!$P$3:$P$5) -> 0 | R6: =SUBTOTAL(109,'IN4'!$R$3:$R$5) -> 0
K8: =+(P8+R8)/'IN4'!$K$6 -> 0 | P8: =+SUM('IN4'!$P$3:$P$5)-SUM(AY3:AY5)-SUM(BI3:BJ5) -> 0 | R8: =+SUM('IN4'!$R$3:$R$5)-SUM(AS3:AS5)-SUM(BC3:BC5)-SUM(AD3:AD5) -> 0 | T8: =SUMPRODUCT(T3:T5,K3:K5)/SUM(K3:K5) -> 0
P9: =+P8/'IN4'!$P$6 -> #DIV/0! | R9: =+R8/'IN4'!$R$6 -> #DIV/0!

Sheet IN5
AN1: VERSO MANAGEMENT | AZ1: PARTNERS excluding JM | BJ1: INTRODUCERS | BS1: JM
B2: Index | C2: Opportunity | D2: Sourcing Contract ref | E2: Cost per Share | F2: Investor Last Name | G2: Investor Middle Name | H2: Investor First Name | I2: Investor Entity | J2: Vehicle | K2: Amount invested | L2: Price per Share | M2: Number of shares invested | N2: Contract Date | O2: Spread PPS | P2: Spread PPS Fees | Q2: Subscription fees % | R2: Subscription fees | S2: Management Fee | T2: Performance fees 1 | U2: Threshold 1 | V2: Performance fees 2 | W2: Threshold 2 | X2: Drawn Down Annual Interest Amount | Y2: Undrawn Down Annual Interest Amount | Z2: Interest Spread | AA2: Gross Interest | AB2: Performance - Interest Spread | AC2: Discount | AD2: Comments | AE2: TO DO | AI2: BD Fees % | AJ2: BD fees | AK2: FINRA fees in share | AL2: FINRA fees | AN2: Subscription fees % | AO2: Subscription fees | AP2: Performance fees 1 | AQ2: Threshold 1 | AR2: Performance fees 2 | AS2: Threshold 2 | AT2: Spread PPS | AU2: Spread PPS Fees | AV2: Drawn Down Annual Interest Spread | AW2: Undrawn Down Annual Interest Spread | AY2: Name | AZ2: Subscription fees % | BA2: Subscription fees | BB2: Performance fees 1 | BC2: Threshold 1 | BD2: Performance fees 2 | BE2: Threshold 2 | BF2: Spread PPS | BG2: Spread PPS Fees | BI2: Name | BJ2: Subscription fees % | BK2: Subscription fees | BL2: Performance fees 1 | BM2: Threshold 1 | BN2: Performance fees 2 | BO2: Threshold 2 | BP2: Spread PPS | BQ2: Spread PPS Fees | BS2: CHECK | BT2: CHECK
B3: 1 | C3: MINDELL DEBT | D3: Revolving Credit | E3: 10000 | F3: GATZ | H3: Tom | J3: IN5 | K3: 100000 | L3: 10000 | M3: 10 | N3: 28/09/2022 | O3: =L3-E3 -> 0 | P3: =O3*'IN5'!$M3 -> 0 | Q3: 0 | R3: =+'IN5'!$K3*'IN5'!$Q3 -> 0 | S3: 0 | T3: 0 | U3: 0x | X3: 0.09 | Y3: 0.055 | Z3: 0.01 | AA3: =10000+1666.67 -> 11666.67 | AB3: =10%*AA3 -> 1166.667 | AC3: 0.2 | AI3: 0 | AJ3: =+AI3*'IN5'!$K3 -> 0 | AK3: 0 | AL3: =+AK3*'IN5'!$M3 -> 0 | AN3: 0 | AO3: =+AN3*'IN5'!$K3 -> 0 | AP3: 0 | AQ3: 0x | AT3: 0 | AU3: =+AT3*'IN5'!$M3 -> 0 | AV3: 0.01 | AZ3: 0 | BA3: =+AZ3*'IN5'!$K3 -> 0 | BB3: 0 | BC3: 0x | BF3: 0 | BG3: =+BF3*'IN5'!$M3 -> 0 | BJ3: 0 | BK3: =+BJ3*'IN5'!$K3 -> 0 | BL3: 0 | BM3: 0x | BP3: 0 | BQ3: =+BP3*'IN5'!$M3 -> 0 | BS3: ='IN5'!$T3-BB3-BL3-AP3 -> 0 | BT3: ='IN5'!$Q3-AN3-AZ3-BJ3 -> 0
B4: 2 | C4: MINDELL DEBT | D4: Revolving Credit | E4: 10000 | I4: VERSO Holdings S.à r.l. | J4: IN5 | K4: 250000 | L4: 10000 | M4: 25 | N4: 20/10/2022 | O4: =L4-E4 -> 0 | P4: =O4*'IN5'!$M4 -> 0 | Q4: 0 | R4: =+'IN5'!$K4*'IN5'!$Q4 -> 0 | S4: 0 | T4: 0 | U4: 0x | X4: 0.09 | Y4: 0.05 | Z4: 0.01 | AA4: =25000+4166.67 -> 29166.67 | AB4: =10%*AA4 -> 2916.667 | AC4: 0.2 | AI4: 0 | AJ4: =+AI4*'IN5'!$K4 -> 0 | AK4: 0 | AL4: =+AK4*'IN5'!$M4 -> 0 | AN4: 0 | AO4: =+AN4*'IN5'!$K4 -> 0 | AP4: 0 | AQ4: 0x | AT4: 0 | AU4: =+AT4*'IN5'!$M4 -> 0 | AV4: 0.02 | AZ4: 0 | BA4: =+AZ4*'IN5'!$K4 -> 0 | BB4: 0 | BC4: 0x | BF4: 0 | BG4: =+BF4*'IN5'!$M4 -> 0 | BJ4: 0 | BK4: =+BJ4*'IN5'!$K4 -> 0 | BL4: 0 | BM4: 0x | BP4: 0 | BQ4: =+BP4*'IN5'!$M4 -> 0 | BS4: ='IN5'!$T4-BB4-BL4-AP4 -> 0 | BT4: ='IN5'!$Q4-AN4-AZ4-BJ4 -> 0
B5: 3 | C5: MINDELL DEBT | D5: Revolving Credit | E5: 10000 | I5: Improvitae B.V. | J5: IN5 | K5: 100000 | L5: 10000 | M5: 10 | N5: 44691 | O5: =L5-E5 -> 0 | P5: =O5*'IN5'!$M5 -> 0 | Q5: 0 | R5: =+'IN5'!$K5*'IN5'!$Q5 -> 0 | S5: 0 | T5: 0 | U5: 0x | X5: 0.09 | Y5: 0.055 | Z5: 0.01 | AA5: =10000+1666.67 -> 11666.67 | AB5: =10%*AA5 -> 1166.667 | AC5: 0.2 | AI5: 0 | AJ5: =+AI5*'IN5'!$K5 -> 0 | AK5: 0 | AL5: =+AK5*'IN5'!$M5 -> 0 | AN5: 0 | AO5: =+AN5*'IN5'!$K5 -> 0 | AP5: 0 | AQ5: 0x | AT5: 0 | AU5: =+AT5*'IN5'!$M5 -> 0 | AV5: 0.01 | AZ5: 0 | BA5: =+AZ5*'IN5'!$K5 -> 0 | BB5: 0 | BC5: 0x | BF5: 0 | BG5: =+BF5*'IN5'!$M5 -> 0 | BJ5: 0 | BK5: =+BJ5*'IN5'!$K5 -> 0 | BL5: 0 | BM5: 0x | BP5: 0 | BQ5: =+BP5*'IN5'!$M5 -> 0 | BS5: ='IN5'!$T5-BB5-BL5-AP5 -> 0 | BT5: ='IN5'!$Q5-AN5-AZ5-BJ5 -> 0
B6: 4 | C6: MINDELL DEBT | D6: Revolving Credit | E6: 10000 | F6: GIRAUD | H6: François-Xavier | J6: IN5 | K6: 50000 | L6: 10000 | M6: 5 | N6: 44875 | O6: =L6-E6 -> 0 | P6: =O6*'IN5'!$M6 -> 0 | Q6: 0 | R6: =+'IN5'!$K6*'IN5'!$Q6 -> 0 | S6: 0 | T6: 0 | U6: 0x | X6: 0.09 | Y6: 0.055 | Z6: 0.01 | AA6: =5000+833.33 -> 5833.33 | AB6: =10%*AA6 -> 583.333 | AC6: 0.2 | AI6: 0 | AJ6: =+AI6*'IN5'!$K6 -> 0 | AK6: 0 | AL6: =+AK6*'IN5'!$M6 -> 0 | AN6: 0 | AO6: =+AN6*'IN5'!$K6 -> 0 | AP6: 0 | AQ6: 0x | AT6: 0 | AU6: =+AT6*'IN5'!$M6 -> 0 | AV6: 0.01 | AZ6: 0 | BA6: =+AZ6*'IN5'!$K6 -> 0 | BB6: 0 | BC6: 0x | BF6: 0 | BG6: =+BF6*'IN5'!$M6 -> 0 | BJ6: 0 | BK6: =+BJ6*'IN5'!$K6 -> 0 | BL6: 0 | BM6: 0x | BP6: 0 | BQ6: =+BP6*'IN5'!$M6 -> 0 | BS6: ='IN5'!$T6-BB6-BL6-AP6 -> 0 | BT6: ='IN5'!$Q6-AN6-AZ6-BJ6 -> 0
B7: 5 | C7: MINDELL DEBT | D7: Revolving Credit | E7: 10000 | I7: Star of the Sea Limited | J7: IN5 | K7: 150000 | L7: 10000 | M7: 15 | N7: 27/10/2022 | O7: =L7-E7 -> 0 | P7: =O7*'IN5'!$M7 -> 0 | Q7: 0 | R7: =+'IN5'!$K7*'IN5'!$Q7 -> 0 | S7: 0 | T7: 0 | U7: 0x | X7: 0.09 | Y7: 0.055 | Z7: 0.01 | AA7: =15000+2500 -> 17500 | AB7: =10%*AA7 -> 1750 | AC7: 0.2 | AI7: 0 | AJ7: =+AI7*'IN5'!$K7 -> 0 | AK7: 0 | AL7: =+AK7*'IN5'!$M7 -> 0 | AN7: 0 | AO7: =+AN7*'IN5'!$K7 -> 0 | AP7: 0 | AQ7: 0x | AT7: 0 | AU7: =+AT7*'IN5'!$M7 -> 0 | AV7: 0.01 | AZ7: 0 | BA7: =+AZ7*'IN5'!$K7 -> 0 | BB7: 0 | BC7: 0x | BF7: 0 | BG7: =+BF7*'IN5'!$M7 -> 0 | BJ7: 0 | BK7: =+BJ7*'IN5'!$K7 -> 0 | BL7: 0 | BM7: 0x | BP7: 0 | BQ7: =+BP7*'IN5'!$M7 -> 0 | BS7: ='IN5'!$T7-BB7-BL7-AP7 -> 0 | BT7: ='IN5'!$Q7-AN7-AZ7-BJ7 -> 0
B8: 6 | C8: MINDELL DEBT | D8: Revolving Credit | E8: 10000 | F8: WYDLER | H8: Nicolas | J8: IN5 | K8: 50000 | L8: 10000 | M8: 5 | N8: 24/10/2022 | O8: =L8-E8 -> 0 | P8: =O8*'IN5'!$M8 -> 0 | Q8: 0 | R8: =+'IN5'!$K8*'IN5'!$Q8 -> 0 | S8: 0 | T8: 0 | U8: 0x | X8: 0.09 | Y8: 0.055 | Z8: 0.01 | AA8: =5000+833.33 -> 5833.33 | AB8: =10%*AA8 -> 583.333 | AC8: 0.2 | AI8: 0 | AJ8: =+AI8*'IN5'!$K8 -> 0 | AK8: 0 | AL8: =+AK8*'IN5'!$M8 -> 0 | AN8: 0 | AO8: =+AN8*'IN5'!$K8 -> 0 | AP8: 0 | AQ8: 0x | AT8: 0 | AU8: =+AT8*'IN5'!$M8 -> 0 | AV8: 0.01 | AZ8: 0 | BA8: =+AZ8*'IN5'!$K8 -> 0 | BB8: 0 | BC8: 0x | BF8: 0 | BG8: =+BF8*'IN5'!$M8 -> 0 | BJ8: 0 | BK8: =+BJ8*'IN5'!$K8 -> 0 | BL8: 0 | BM8: 0x | BP8: 0 | BQ8: =+BP8*'IN5'!$M8 -> 0 | BS8: ='IN5'!$T8-BB8-BL8-AP8 -> 0 | BT8: ='IN5'!$Q8-AN8-AZ8-BJ8 -> 0
B9: 7 | C9: MINDELL DEBT | D9: Revolving Credit | E9: 10000 | J9: IN5 | K9: 0 | L9: 10000 | M9: 0 | N9: 27/01/2022 | O9: =L9-E9 -> 0 | P9: =O9*'IN5'!$M9 -> 0 | Q9: 0 | R9: =+'IN5'!$K9*'IN5'!$Q9 -> 0 | S9: 0 | T9: 0 | U9: 0x | X9: 0.09 | Y9: 0.055 | Z9: 0.01 | AC9: 0.2 | AI9: 0 | AJ9: =+AI9*'IN5'!$K9 -> 0 | AK9: 0 | AL9: =+AK9*'IN5'!$M9 -> 0 | AN9: 0 | AO9: =+AN9*'IN5'!$K9 -> 0 | AP9: 0 | AQ9: 0x | AT9: 0 | AU9: =+AT9*'IN5'!$M9 -> 0 | AZ9: 0 | BA9: =+AZ9*'IN5'!$K9 -> 0 | BB9: 0 | BC9: 0x | BF9: 0 | BG9: =+BF9*'IN5'!$M9 -> 0 | BJ9: 0 | BK9: =+BJ9*'IN5'!$K9 -> 0 | BL9: 0 | BM9: 0x | BP9: 0 | BQ9: =+BP9*'IN5'!$M9 -> 0 | BS9: ='IN5'!$T9-BB9-BL9-AP9 -> 0 | BT9: ='IN5'!$Q9-AN9-AZ9-BJ9 -> 0
B10: 8 | C10: MINDELL DEBT | D10: Revolving Credit | E10: 10000 | J10: IN5 | K10: 0 | L10: 10000 | M10: 0 | N10: 24/02/2022 | O10: =L10-E10 -> 0 | P10: =O10*'IN5'!$M10 -> 0 | Q10: 0 | R10: =+'IN5'!$K10*'IN5'!$Q10 -> 0 | S10: 0 | T10: 0 | U10: 0x | X10: 0.09 | Y10: 0.055 | Z10: 0.01 | AC10: 0.2 | AI10: 0 | AJ10: =+AI10*'IN5'!$K10 -> 0 | AK10: 0 | AL10: =+AK10*'IN5'!$M10 -> 0 | AN10: 0 | AO10: =+AN10*'IN5'!$K10 -> 0 | AP10: 0 | AQ10: 0x | AT10: 0 | AU10: =+AT10*'IN5'!$M10 -> 0 | AZ10: 0 | BA10: =+AZ10*'IN5'!$K10 -> 0 | BB10: 0 | BC10: 0x | BF10: 0 | BG10: =+BF10*'IN5'!$M10 -> 0 | BJ10: 0 | BK10: =+BJ10*'IN5'!$K10 -> 0 | BL10: 0 | BM10: 0x | BP10: 0 | BQ10: =+BP10*'IN5'!$M10 -> 0 | BS10: ='IN5'!$T10-BB10-BL10-AP10 -> 0 | BT10: ='IN5'!$Q10-AN10-AZ10-BJ10 -> 0
B11: 9 | C11: MINDELL DEBT | D11: Revolving Credit | E11: 10000 | J11: IN5 | K11: 0 | L11: 10000 | M11: 0 | N11: 27/01/2022 | O11: =L11-E11 -> 0 | P11: =O11*'IN5'!$M11 -> 0 | Q11: 0 | R11: =+'IN5'!$K11*'IN5'!$Q11 -> 0 | S11: 0 | T11: 0 | U11: 0x | AI11: 0 | AJ11: =+AI11*'IN5'!$K11 -> 0 | AK11: 0 | AL11: =+AK11*'IN5'!$M11 -> 0 | AN11: 0 | AO11: =+AN11*'IN5'!$K11 -> 0 | AP11: 0 | AQ11: 0x | AT11: 0 | AU11: =+AT11*'IN5'!$M11 -> 0 | AZ11: 0 | BA11: =+AZ11*'IN5'!$K11 -> 0 | BB11: 0 | BC11: 0x | BF11: 0 | BG11: =+BF11*'IN5'!$M11 -> 0 | BJ11: 0 | BK11: =+BJ11*'IN5'!$K11 -> 0 | BL11: 0 | BM11: 0x | BP11: 0 | BQ11: =+BP11*'IN5'!$M11 -> 0 | BS11: ='IN5'!$T11-BB11-BL11-AP11 -> 0 | BT11: ='IN5'!$Q11-AN11-AZ11-BJ11 -> 0
C12: Total | K12: =SUBTOTAL(109,'IN5'!$K$3:$K$11) -> 700000 | M12: =SUBTOTAL(109,'IN5'!$M$3:$M$11) -> 70 | P12: =SUBTOTAL(109,'IN5'!$P$3:$P$11) -> 0 | R12: =SUBTOTAL(109,'IN5'!$R$3:$R$11) -> 0 | AA12: =SUBTOTAL(109,'IN5'!$AA$3:$AA$11) -> 81666.67 | AB12: =SUBTOTAL(109,'IN5'!$AB$3:$AB$11) -> 8166.667
K14: =+(P14+R14)/'IN5'!$K$12 -> 0 | P14: =+SUM('IN5'!$P$3:$P$11)-SUM(BG3:BG11)-SUM(BQ3:BR11) -> 0 | R14: =+SUM('IN5'!$R$3:$R$11)-SUM(BA3:BA11)-SUM(BK3:BK11)-SUM(AJ3:AJ11) -> 0 | T14: =SUMPRODUCT(T3:T11,K3:K11)/SUM(K3:K11) -> 0
P15: =+P14/'IN5'!$P$12 -> #DIV/0! | R15: =+R14/'IN5'!$R$12 -> #DIV/0!

Sheet IN6
AI1: VERSO MANAGEMENT | AS1: PARTNERS excluding JM | BC1: INTRODUCERS | BL1: JM
B2: Index | C2: Opportunity | D2: Sourcing Contract ref | E2: Cost per Share | F2: Investor Last Name | G2: Investor Middle Name | H2: Investor First Name | I2: Investor Entity | J2: Vehicle | K2: Amount invested | L2: Price per Share | M2: Number of shares invested | N2: OWNERSHIP POSITION | O2: Contract Date | P2: Spread PPS | Q2: Spread PPS Fees | R2: Subscription fees % | S2: Subscription fees | T2: Management Fee | U2: Performance fees 1 | V2: Threshold 1 | W2: Performance fees 2 | X2: Threshold 2 | Y2: Comments | Z2: TO DO | AD2: BD Fees % | AE2: BD fees | AF2: FINRA fees in share | AG2: FINRA fees | AI2: Subscription fees % | AJ2: Subscription fees | AK2: Performance fees 1 | AL2: Threshold 1 | AM2: Performance fees 2 | AN2: Threshold 2 | AO2: Spread PPS | AP2: Spread PPS Fees | AR2: Name | AS2: Subscription fees % | AT2: Subscription fees | AU2: Performance fees 1 | AV2: Threshold 1 | AW2: Performance fees 2 | AX2: Threshold 2 | AY2: Spread PPS | AZ2: Spread PPS Fees | BB2: Name | BC2: Subscription fees % | BD2: Subscription fees | BE2: Performance fees 1 | BF2: Threshold 1 | BG2: Performance fees 2 | BH2: Threshold 2 | BI2: Spread PPS | BJ2: Spread PPS Fees | BL2: CHECK | BM2: CHECK
B3: 1 | C3: VOYAGE FOODS | D3: Series A Preferred | E3: 4.9879 | I3: Wymo Finance Limited | J3: IN6 | K3: 330000 | L3: 4.9879 | M3: 66160 | N3: 0 | O3: 44869 | P3: =L3-E3 -> 0 | Q3: =P3*'IN6'!$M3 -> 0 | R3: 0.02 | S3: =+'IN6'!$K3*'IN6'!$R3 -> 6600 | T3: 0 | U3: 0.2 | V3: 0x | Y3: Transfer to mahesh | AD3: 0 | AE3: =+AD3*'IN6'!$K3 -> 0 | AF3: 0 | AG3: =+AF3*'IN6'!$M3 -> 0 | AI3: 0.01 | AJ3: =+AI3*'IN6'!$K3 -> 3300 | AK3: 0.03 | AL3: 0x | AO3: 0 | AP3: =+AO3*'IN6'!$M3 -> 0 | AS3: 0 | AT3: =+AS3*'IN6'!$K3 -> 0 | AU3: 0 | AV3: 0x | AY3: 0 | AZ3: =+AY3*'IN6'!$M3 -> 0 | BB3: SET CAP | BC3: 0.01 | BD3: =+BC3*'IN6'!$K3 -> 3300 | BE3: 0.17 | BF3: 0x | BI3: 0 | BJ3: =+BI3*'IN6'!$M3 -> 0 | BL3: ='IN6'!$U3-AU3-BE3-AK3 -> 0 | BM3: ='IN6'!$R3-AI3-AS3-BC3 -> 0
B4: 2 | C4: VOYAGE FOODS | D4: Series A Preferred | E4: 4.9879 | F4: TATA | H4: Neville | J4: IN6 | K4: 10000 | L4: 4.9879 | M4: 2004 | N4: =M4 -> 2004 | O4: 14/04/2022 | P4: =L4-E4 -> 0 | Q4: =P4*'IN6'!$M4 -> 0 | R4: 0 | S4: =+'IN6'!$K4*'IN6'!$R4 -> 0 | T4: 0 | U4: 0 | V4: 0x | AD4: 0 | AE4: =+AD4*'IN6'!$K4 -> 0 | AF4: 0 | AG4: =+AF4*'IN6'!$M4 -> 0 | AI4: 0 | AJ4: =+AI4*'IN6'!$K4 -> 0 | AK4: 0 | AL4: 0x | AO4: 0 | AP4: =+AO4*'IN6'!$M4 -> 0 | AS4: 0 | AT4: =+AS4*'IN6'!$K4 -> 0 | AU4: 0 | AV4: 0x | AY4: 0 | AZ4: =+AY4*'IN6'!$M4 -> 0 | BC4: 0 | BD4: =+BC4*'IN6'!$K4 -> 0 | BE4: 0 | BF4: 0x | BI4: 0 | BJ4: =+BI4*'IN6'!$M4 -> 0 | BL4: ='IN6'!$U4-AU4-BE4-AK4 -> 0 | BM4: ='IN6'!$R4-AI4-AS4-BC4 -> 0
B5: 3 | C5: VOYAGE FOODS | D5: Series A Preferred | E5: 4.9879 | J5: IN6 | K5: 0 | L5: 4.9879 | M5: 0 | N5: =M5 -> 0 | O5: 24/01/2022 | P5: =L5-E5 -> 0 | Q5: =P5*'IN6'!$M5 -> 0 | R5: 0 | S5: =+'IN6'!$K5*'IN6'!$R5 -> 0 | T5: 0 | U5: 0 | V5: 0x | AD5: 0 | AE5: =+AD5*'IN6'!$K5 -> 0 | AF5: 0 | AG5: =+AF5*'IN6'!$M5 -> 0 | AI5: 0 | AJ5: =+AI5*'IN6'!$K5 -> 0 | AK5: 0 | AL5: 0x | AO5: 0 | AP5: =+AO5*'IN6'!$M5 -> 0 | AS5: 0 | AT5: =+AS5*'IN6'!$K5 -> 0 | AU5: 0 | AV5: 0x | AY5: 0 | AZ5: =+AY5*'IN6'!$M5 -> 0 | BC5: 0 | BD5: =+BC5*'IN6'!$K5 -> 0 | BE5: 0 | BF5: 0x | BI5: 0 | BJ5: =+BI5*'IN6'!$M5 -> 0 | BL5: ='IN6'!$U5-AU5-BE5-AK5 -> 0 | BM5: ='IN6'!$R5-AI5-AS5-BC5 -> 0
B6: 4 | C6: VOYAGE FOODS | D6: Series A Preferred | E6: 4.9879 | J6: IN6 | K6: 0 | L6: 4.9879 | M6: 0 | N6: =M6 -> 0 | O6: 27/01/2022 | P6: =L6-E6 -> 0 | Q6: =P6*'IN6'!$M6 -> 0 | R6: 0 | S6: =+'IN6'!$K6*'IN6'!$R6 -> 0 | T6: 0 | U6: 0 | V6: 0x | AD6: 0 | AE6: =+AD6*'IN6'!$K6 -> 0 | AF6: 0 | AG6: =+AF6*'IN6'!$M6 -> 0 | AI6: 0 | AJ6: =+AI6*'IN6'!$K6 -> 0 | AK6: 0 | AL6: 0x | AO6: 0 | AP6: =+AO6*'IN6'!$M6 -> 0 | AS6: 0 | AT6: =+AS6*'IN6'!$K6 -> 0 | AU6: 0 | AV6: 0x | AY6: 0 | AZ6: =+AY6*'IN6'!$M6 -> 0 | BC6: 0 | BD6: =+BC6*'IN6'!$K6 -> 0 | BE6: 0 | BF6: 0x | BI6: 0 | BJ6: =+BI6*'IN6'!$M6 -> 0 | BL6: ='IN6'!$U6-AU6-BE6-AK6 -> 0 | BM6: ='IN6'!$R6-AI6-AS6-BC6 -> 0
B7: 5 | C7: VOYAGE FOODS | D7: Series A Preferred | E7: 4.9879 | J7: IN6 | K7: 0 | L7: 4.9879 | M7: 0 | N7: =M7 -> 0 | O7: 27/01/2022 | P7: =L7-E7 -> 0 | Q7: =P7*'IN6'!$M7 -> 0 | R7: 0 | S7: =+'IN6'!$K7*'IN6'!$R7 -> 0 | T7: 0 | U7: 0 | V7: 0x | AD7: 0 | AE7: =+AD7*'IN6'!$K7 -> 0 | AF7: 0 | AG7: =+AF7*'IN6'!$M7 -> 0 | AI7: 0 | AJ7: =+AI7*'IN6'!$K7 -> 0 | AK7: 0 | AL7: 0x | AO7: 0 | AP7: =+AO7*'IN6'!$M7 -> 0 | AS7: 0 | AT7: =+AS7*'IN6'!$K7 -> 0 | AU7: 0 | AV7: 0x | AY7: 0 | AZ7: =+AY7*'IN6'!$M7 -> 0 | BC7: 0 | BD7: =+BC7*'IN6'!$K7 -> 0 | BE7: 0 | BF7: 0x | BI7: 0 | BJ7: =+BI7*'IN6'!$M7 -> 0 | BL7: ='IN6'!$U7-AU7-BE7-AK7 -> 0 | BM7: ='IN6'!$R7-AI7-AS7-BC7 -> 0
B8: 6 | C8: VOYAGE FOODS | D8: Series A Preferred | E8: 4.9879 | J8: IN6 | K8: 0 | L8: 4.9879 | M8: 0 | N8: =M8 -> 0 | O8: 27/01/2022 | P8: =L8-E8 -> 0 | Q8: =P8*'IN6'!$M8 -> 0 | R8: 0 | S8: =+'IN6'!$K8*'IN6'!$R8 -> 0 | T8: 0 | U8: 0 | V8: 0x | AD8: 0 | AE8: =+AD8*'IN6'!$K8 -> 0 | AF8: 0 | AG8: =+AF8*'IN6'!$M8 -> 0 | AI8: 0 | AJ8: =+AI8*'IN6'!$K8 -> 0 | AK8: 0 | AL8: 0x | AO8: 0 | AP8: =+AO8*'IN6'!$M8 -> 0 | AS8: 0 | AT8: =+AS8*'IN6'!$K8 -> 0 | AU8: 0 | AV8: 0x | AY8: 0 | AZ8: =+AY8*'IN6'!$M8 -> 0 | BC8: 0 | BD8: =+BC8*'IN6'!$K8 -> 0 | BE8: 0 | BF8: 0x | BI8: 0 | BJ8: =+BI8*'IN6'!$M8 -> 0 | BL8: ='IN6'!$U8-AU8-BE8-AK8 -> 0 | BM8: ='IN6'!$R8-AI8-AS8-BC8 -> 0
B9: 7 | C9: VOYAGE FOODS | D9: Series A Preferred | E9: 4.9879 | J9: IN6 | K9: 0 | L9: 4.9879 | M9: 0 | N9: =M9 -> 0 | O9: 27/01/2022 | P9: =L9-E9 -> 0 | Q9: =P9*'IN6'!$M9 -> 0 | R9: 0 | S9: =+'IN6'!$K9*'IN6'!$R9 -> 0 | T9: 0 | U9: 0 | V9: 0x | AD9: 0 | AE9: =+AD9*'IN6'!$K9 -> 0 | AF9: 0 | AG9: =+AF9*'IN6'!$M9 -> 0 | AI9: 0 | AJ9: =+AI9*'IN6'!$K9 -> 0 | AK9: 0 | AL9: 0x | AO9: 0 | AP9: =+AO9*'IN6'!$M9 -> 0 | AS9: 0 | AT9: =+AS9*'IN6'!$K9 -> 0 | AU9: 0 | AV9: 0x | AY9: 0 | AZ9: =+AY9*'IN6'!$M9 -> 0 | BC9: 0 | BD9: =+BC9*'IN6'!$K9 -> 0 | BE9: 0 | BF9: 0x | BI9: 0 | BJ9: =+BI9*'IN6'!$M9 -> 0 | BL9: ='IN6'!$U9-AU9-BE9-AK9 -> 0 | BM9: ='IN6'!$R9-AI9-AS9-BC9 -> 0
B10: 8 | C10: VOYAGE FOODS | D10: Series A Preferred | E10: 4.9879 | J10: IN6 | K10: 0 | L10: 4.9879 | M10: 0 | N10: =M10 -> 0 | O10: 24/02/2022 | P10: =L10-E10 -> 0 | Q10: =P10*'IN6'!$M10 -> 0 | R10: 0 | S10: =+'IN6'!$K10*'IN6'!$R10 -> 0 | T10: 0 | U10: 0 | V10: 0x | AD10: 0 | AE10: =+AD10*'IN6'!$K10 -> 0 | AF10: 0 | AG10: =+AF10*'IN6'!$M10 -> 0 | AI10: 0 | AJ10: =+AI10*'IN6'!$K10 -> 0 | AK10: 0 | AL10: 0x | AO10: 0 | AP10: =+AO10*'IN6'!$M10 -> 0 | AS10: 0 | AT10: =+AS10*'IN6'!$K10 -> 0 | AU10: 0 | AV10: 0x | AY10: 0 | AZ10: =+AY10*'IN6'!$M10 -> 0 | BC10: 0 | BD10: =+BC10*'IN6'!$K10 -> 0 | BE10: 0 | BF10: 0x | BI10: 0 | BJ10: =+BI10*'IN6'!$M10 -> 0 | BL10: ='IN6'!$U10-AU10-BE10-AK10 -> 0 | BM10: ='IN6'!$R10-AI10-AS10-BC10 -> 0
B11: 9 | C11: VOYAGE FOODS | D11: Series A Preferred | E11: 4.9879 | J11: IN6 | K11: 0 | L11: 4.9879 | M11: 0 | N11: =M11 -> 0 | O11: 27/01/2022 | P11: =L11-E11 -> 0 | Q11: =P11*'IN6'!$M11 -> 0 | R11: 0 | S11: =+'IN6'!$K11*'IN6'!$R11 -> 0 | T11: 0 | U11: 0 | V11: 0x | AD11: 0 | AE11: =+AD11*'IN6'!$K11 -> 0 | AF11: 0 | AG11: =+AF11*'IN6'!$M11 -> 0 | AI11: 0 | AJ11: =+AI11*'IN6'!$K11 -> 0 | AK11: 0 | AL11: 0x | AO11: 0 | AP11: =+AO11*'IN6'!$M11 -> 0 | AS11: 0 | AT11: =+AS11*'IN6'!$K11 -> 0 | AU11: 0 | AV11: 0x | AY11: 0 | AZ11: =+AY11*'IN6'!$M11 -> 0 | BC11: 0 | BD11: =+BC11*'IN6'!$K11 -> 0 | BE11: 0 | BF11: 0x | BI11: 0 | BJ11: =+BI11*'IN6'!$M11 -> 0 | BL11: ='IN6'!$U11-AU11-BE11-AK11 -> 0 | BM11: ='IN6'!$R11-AI11-AS11-BC11 -> 0
C12: Total | K12: =SUBTOTAL(109,'IN6'!$K$3:$K$11) -> 340000 | M12: =SUBTOTAL(109,'IN6'!$M$3:$M$11) -> 68164 | N12: =SUBTOTAL(109,'IN6'!$N$3:$N$11) -> 2004 | Q12: =SUBTOTAL(109,'IN6'!$Q$3:$Q$11) -> 0 | S12: =SUBTOTAL(109,'IN6'!$S$3:$S$11) -> 6600
K14: =+(Q14+S14)/'IN6'!$K$12 -> 0.0097058824 | Q14: =+SUM('IN6'!$Q$3:$Q$11)-SUM(AZ3:AZ11)-SUM(BJ3:BK11) -> 0 | S14: =+SUM('IN6'!$S$3:$S$11)-SUM(AT3:AT11)-SUM(BD3:BD11)-SUM(AE3:AE11) -> 3300 | U14: =SUMPRODUCT(U3:U11,K3:K11)/SUM(K3:K11) -> 0.19411765
Q15: =+Q14/'IN6'!$Q$12 -> #DIV/0! | S15: =+S14/'IN6'!$S$12 -> 0.5

Sheet IN7
AH1: VERSO CAPITAL | AR1: PARTNERS excluding JM | BB1: INTRODUCERS | BK1: JM
B2: Index | C2: Opportunity | D2: Sourcing Contract ref | E2: Cost per Share | F2: Investor Last Name | G2: Investor Middle Name | H2: Investor First Name | I2: Investor Entity | J2: Vehicle | K2: Amount invested | L2: Price per Share | M2: Number of shares invested | N2: Contract Date | O2: Spread PPS | P2: Spread PPS Fees | Q2: Subscription fees % | R2: Subscription fees | S2: Management Fee | T2: Performance fees 1 | U2: Threshold 1 | V2: Performance fees 2 | W2: Threshold 2 | X2: Comments | Y2: TO DO | AC2: BD Fees % | AD2: BD fees | AE2: FINRA fees in share | AF2: FINRA fees | AH2: Subscription fees % | AI2: Subscription fees | AJ2: Performance fees 1 | AK2: Threshold 1 | AL2: Performance fees 2 | AM2: Threshold 2 | AN2: Spread PPS | AO2: Spread PPS Fees | AQ2: Name | AR2: Subscription fees % | AS2: Subscription fees | AT2: Performance fees 1 | AU2: Threshold 1 | AV2: Performance fees 2 | AW2: Threshold 2 | AX2: Spread PPS | AY2: Spread PPS Fees | BA2: Name | BB2: Subscription fees % | BC2: Subscription fees | BD2: Performance fees 1 | BE2: Threshold 1 | BF2: Performance fees 2 | BG2: Threshold 2 | BH2: Spread PPS | BI2: Spread PPS Fees | BK2: CHECK | BL2: CHECK
B3: 1 | C3: THIRD COLLECTIVE 3CV TOPL | E3: 1 | J3: IN7 | K3: 0 | L3: 1 | M3: 0 | N3: 44869 | O3: =L3-E3 -> 0 | P3: =O3*'IN7'!$M3 -> 0 | Q3: 0 | R3: =+'IN7'!$K3*'IN7'!$Q3 -> 0 | S3: 0 | T3: 0 | U3: 0x | AC3: 0 | AD3: =+AC3*'IN7'!$K3 -> 0 | AE3: 0 | AF3: =+AE3*'IN7'!$M3 -> 0 | AH3: 0 | AI3: =+AH3*'IN7'!$K3 -> 0 | AJ3: 0 | AK3: 0x | AN3: 0 | AO3: =+AN3*'IN7'!$M3 -> 0 | AR3: 0 | AS3: =+AR3*'IN7'!$K3 -> 0 | AT3: 0 | AU3: 0x | AX3: 0 | AY3: =+AX3*'IN7'!$M3 -> 0 | BB3: 0 | BC3: =+BB3*'IN7'!$K3 -> 0 | BD3: 0 | BE3: 0x | BH3: 0 | BI3: =+BH3*'IN7'!$M3 -> 0 | BK3: ='IN7'!$T3-AT3-BD3-AJ3 -> 0 | BL3: ='IN7'!$Q3-AH3-AR3-BB3 -> 0
B4: 2 | E4: 1 | J4: IN7 | K4: 0 | L4: 1 | M4: 0 | N4: 14/04/2022 | O4: =L4-E4 -> 0 | P4: =O4*'IN7'!$M4 -> 0 | Q4: 0 | R4: =+'IN7'!$K4*'IN7'!$Q4 -> 0 | S4: 0 | T4: 0 | U4: 0x | AC4: 0 | AD4: =+AC4*'IN7'!$K4 -> 0 | AE4: 0 | AF4: =+AE4*'IN7'!$M4 -> 0 | AH4: 0 | AI4: =+AH4*'IN7'!$K4 -> 0 | AJ4: 0 | AK4: 0x | AN4: 0 | AO4: =+AN4*'IN7'!$M4 -> 0 | AR4: 0 | AS4: =+AR4*'IN7'!$K4 -> 0 | AT4: 0 | AU4: 0x | AX4: 0 | AY4: =+AX4*'IN7'!$M4 -> 0 | BB4: 0 | BC4: =+BB4*'IN7'!$K4 -> 0 | BD4: 0 | BE4: 0x | BH4: 0 | BI4: =+BH4*'IN7'!$M4 -> 0 | BK4: ='IN7'!$T4-AT4-BD4-AJ4 -> 0 | BL4: ='IN7'!$Q4-AH4-AR4-BB4 -> 0
B5: 3 | E5: 1 | J5: IN7 | K5: 0 | L5: 1 | M5: 0 | N5: 24/01/2022 | O5: =L5-E5 -> 0 | P5: =O5*'IN7'!$M5 -> 0 | Q5: 0 | R5: =+'IN7'!$K5*'IN7'!$Q5 -> 0 | S5: 0 | T5: 0 | U5: 0x | AC5: 0 | AD5: =+AC5*'IN7'!$K5 -> 0 | AE5: 0 | AF5: =+AE5*'IN7'!$M5 -> 0 | AH5: 0 | AI5: =+AH5*'IN7'!$K5 -> 0 | AJ5: 0 | AK5: 0x | AN5: 0 | AO5: =+AN5*'IN7'!$M5 -> 0 | AR5: 0 | AS5: =+AR5*'IN7'!$K5 -> 0 | AT5: 0 | AU5: 0x | AX5: 0 | AY5: =+AX5*'IN7'!$M5 -> 0 | BB5: 0 | BC5: =+BB5*'IN7'!$K5 -> 0 | BD5: 0 | BE5: 0x | BH5: 0 | BI5: =+BH5*'IN7'!$M5 -> 0 | BK5: ='IN7'!$T5-AT5-BD5-AJ5 -> 0 | BL5: ='IN7'!$Q5-AH5-AR5-BB5 -> 0
B6: 4 | E6: 1 | J6: IN7 | K6: 0 | L6: 1 | M6: 0 | N6: 27/01/2022 | O6: =L6-E6 -> 0 | P6: =O6*'IN7'!$M6 -> 0 | Q6: 0 | R6: =+'IN7'!$K6*'IN7'!$Q6 -> 0 | S6: 0 | T6: 0 | U6: 0x | AC6: 0 | AD6: =+AC6*'IN7'!$K6 -> 0 | AE6: 0 | AF6: =+AE6*'IN7'!$M6 -> 0 | AH6: 0 | AI6: =+AH6*'IN7'!$K6 -> 0 | AJ6: 0 | AK6: 0x | AN6: 0 | AO6: =+AN6*'IN7'!$M6 -> 0 | AR6: 0 | AS6: =+AR6*'IN7'!$K6 -> 0 | AT6: 0 | AU6: 0x | AX6: 0 | AY6: =+AX6*'IN7'!$M6 -> 0 | BB6: 0 | BC6: =+BB6*'IN7'!$K6 -> 0 | BD6: 0 | BE6: 0x | BH6: 0 | BI6: =+BH6*'IN7'!$M6 -> 0 | BK6: ='IN7'!$T6-AT6-BD6-AJ6 -> 0 | BL6: ='IN7'!$Q6-AH6-AR6-BB6 -> 0
B7: 5 | E7: 1 | J7: IN7 | K7: 0 | L7: 1 | M7: 0 | N7: 27/01/2022 | O7: =L7-E7 -> 0 | P7: =O7*'IN7'!$M7 -> 0 | Q7: 0 | R7: =+'IN7'!$K7*'IN7'!$Q7 -> 0 | S7: 0 | T7: 0 | U7: 0x | AC7: 0 | AD7: =+AC7*'IN7'!$K7 -> 0 | AE7: 0 | AF7: =+AE7*'IN7'!$M7 -> 0 | AH7: 0 | AI7: =+AH7*'IN7'!$K7 -> 0 | AJ7: 0 | AK7: 0x | AN7: 0 | AO7: =+AN7*'IN7'!$M7 -> 0 | AR7: 0 | AS7: =+AR7*'IN7'!$K7 -> 0 | AT7: 0 | AU7: 0x | AX7: 0 | AY7: =+AX7*'IN7'!$M7 -> 0 | BB7: 0 | BC7: =+BB7*'IN7'!$K7 -> 0 | BD7: 0 | BE7: 0x | BH7: 0 | BI7: =+BH7*'IN7'!$M7 -> 0 | BK7: ='IN7'!$T7-AT7-BD7-AJ7 -> 0 | BL7: ='IN7'!$Q7-AH7-AR7-BB7 -> 0
B8: 6 | E8: 1 | J8: IN7 | K8: 0 | L8: 1 | M8: 0 | N8: 27/01/2022 | O8: =L8-E8 -> 0 | P8: =O8*'IN7'!$M8 -> 0 | Q8: 0 | R8: =+'IN7'!$K8*'IN7'!$Q8 -> 0 | S8: 0 | T8: 0 | U8: 0x | AC8: 0 | AD8: =+AC8*'IN7'!$K8 -> 0 | AE8: 0 | AF8: =+AE8*'IN7'!$M8 -> 0 | AH8: 0 | AI8: =+AH8*'IN7'!$K8 -> 0 | AJ8: 0 | AK8: 0x | AN8: 0 | AO8: =+AN8*'IN7'!$M8 -> 0 | AR8: 0 | AS8: =+AR8*'IN7'!$K8 -> 0 | AT8: 0 | AU8: 0x | AX8: 0 | AY8: =+AX8*'IN7'!$M8 -> 0 | BB8: 0 | BC8: =+BB8*'IN7'!$K8 -> 0 | BD8: 0 | BE8: 0x | BH8: 0 | BI8: =+BH8*'IN7'!$M8 -> 0 | BK8: ='IN7'!$T8-AT8-BD8-AJ8 -> 0 | BL8: ='IN7'!$Q8-AH8-AR8-BB8 -> 0
B9: 7 | E9: 1 | J9: IN7 | K9: 0 | L9: 1 | M9: 0 | N9: 27/01/2022 | O9: =L9-E9 -> 0 | P9: =O9*'IN7'!$M9 -> 0 | Q9: 0 | R9: =+'IN7'!$K9*'IN7'!$Q9 -> 0 | S9: 0 | T9: 0 | U9: 0x | AC9: 0 | AD9: =+AC9*'IN7'!$K9 -> 0 | AE9: 0 | AF9: =+AE9*'IN7'!$M9 -> 0 | AH9: 0 | AI9: =+AH9*'IN7'!$K9 -> 0 | AJ9: 0 | AK9: 0x | AN9: 0 | AO9: =+AN9*'IN7'!$M9 -> 0 | AR9: 0 | AS9: =+AR9*'IN7'!$K9 -> 0 | AT9: 0 | AU9: 0x | AX9: 0 | AY9: =+AX9*'IN7'!$M9 -> 0 | BB9: 0 | BC9: =+BB9*'IN7'!$K9 -> 0 | BD9: 0 | BE9: 0x | BH9: 0 | BI9: =+BH9*'IN7'!$M9 -> 0 | BK9: ='IN7'!$T9-AT9-BD9-AJ9 -> 0 | BL9: ='IN7'!$Q9-AH9-AR9-BB9 -> 0
B10: 8 | E10: 1 | J10: IN7 | K10: 0 | L10: 1 | M10: 0 | N10: 24/02/2022 | O10: =L10-E10 -> 0 | P10: =O10*'IN7'!$M10 -> 0 | Q10: 0 | R10: =+'IN7'!$K10*'IN7'!$Q10 -> 0 | S10: 0 | T10: 0 | U10: 0x | AC10: 0 | AD10: =+AC10*'IN7'!$K10 -> 0 | AE10: 0 | AF10: =+AE10*'IN7'!$M10 -> 0 | AH10: 0 | AI10: =+AH10*'IN7'!$K10 -> 0 | AJ10: 0 | AK10: 0x | AN10: 0 | AO10: =+AN10*'IN7'!$M10 -> 0 | AR10: 0 | AS10: =+AR10*'IN7'!$K10 -> 0 | AT10: 0 | AU10: 0x | AX10: 0 | AY10: =+AX10*'IN7'!$M10 -> 0 | BB10: 0 | BC10: =+BB10*'IN7'!$K10 -> 0 | BD10: 0 | BE10: 0x | BH10: 0 | BI10: =+BH10*'IN7'!$M10 -> 0 | BK10: ='IN7'!$T10-AT10-BD10-AJ10 -> 0 | BL10: ='IN7'!$Q10-AH10-AR10-BB10 -> 0
B11: 9 | E11: 1 | J11: IN7 | K11: 0 | L11: 1 | M11: 0 | N11: 27/01/2022 | O11: =L11-E11 -> 0 | P11: =O11*'IN7'!$M11 -> 0 | Q11: 0 | R11: =+'IN7'!$K11*'IN7'!$Q11 -> 0 | S11: 0 | T11: 0 | U11: 0x | AC11: 0 | AD11: =+AC11*'IN7'!$K11 -> 0 | AE11: 0 | AF11: =+AE11*'IN7'!$M11 -> 0 | AH11: 0 | AI11: =+AH11*'IN7'!$K11 -> 0 | AJ11: 0 | AK11: 0x | AN11: 0 | AO11: =+AN11*'IN7'!$M11 -> 0 | AR11: 0 | AS11: =+AR11*'IN7'!$K11 -> 0 | AT11: 0 | AU11: 0x | AX11: 0 | AY11: =+AX11*'IN7'!$M11 -> 0 | BB11: 0 | BC11: =+BB11*'IN7'!$K11 -> 0 | BD11: 0 | BE11: 0x | BH11: 0 | BI11: =+BH11*'IN7'!$M11 -> 0 | BK11: ='IN7'!$T11-AT11-BD11-AJ11 -> 0 | BL11: ='IN7'!$Q11-AH11-AR11-BB11 -> 0
C12: Total | K12: =SUBTOTAL(109,'IN7'!$K$3:$K$11) -> 0 | M12: =SUBTOTAL(109,'IN7'!$M$3:$M$11) -> 0 | P12: =SUBTOTAL(109,'IN7'!$P$3:$P$11) -> 0 | R12: =SUBTOTAL(109,'IN7'!$R$3:$R$11) -> 0
K14: =+(P14+R14)/'IN7'!$K$12 -> #DIV/0! | P14: =+SUM('IN7'!$P$3:$P$11)-SUM(AY3:AY11)-SUM(BI3:BJ11) -> 0 | R14: =+SUM('IN7'!$R$3:$R$11)-SUM(AS3:AS11)-SUM(BC3:BC11)-SUM(AD3:AD11) -> 0 | T14: =SUMPRODUCT(T3:T11,K3:K11)/SUM(K3:K11) -> #DIV/0!
P15: =+P14/'IN7'!$P$12 -> #DIV/0! | R15: =+R14/'IN7'!$R$12 -> #DIV/0!

Sheet IN8
AH1: VERSO CAPITAL | AR1: PARTNERS excluding JM | BB1: INTRODUCERS | BK1: JM
B2: Index | C2: Opportunity | D2: Sourcing Contract ref | E2: Cost per Share | F2: Investor Last Name | G2: Investor Middle Name | H2: Investor First Name | I2: Investor Entity | J2: Vehicle | K2: Amount invested | L2: Price per Share | M2: Number of shares invested | N2: Contract Date | O2: Spread PPS | P2: Spread PPS Fees | Q2: Subscription fees % | R2: Subscription fees | S2: Management Fee | T2: Performance fees 1 | U2: Threshold 1 | V2: Performance fees 2 | W2: Threshold 2 | X2: Comments | Y2: TO DO | AC2: BD Fees % | AD2: BD fees | AE2: FINRA fees in share | AF2: FINRA fees | AH2: Subscription fees % | AI2: Subscription fees | AJ2: Performance fees 1 | AK2: Threshold 1 | AL2: Performance fees 2 | AM2: Threshold 2 | AN2: Spread PPS | AO2: Spread PPS Fees | AQ2: Name | AR2: Subscription fees % | AS2: Subscription fees | AT2: Performance fees 1 | AU2: Threshold 1 | AV2: Performance fees 2 | AW2: Threshold 2 | AX2: Spread PPS | AY2: Spread PPS Fees | BA2: Name | BB2: Subscription fees % | BC2: Subscription fees | BD2: Performance fees 1 | BE2: Threshold 1 | BF2: Performance fees 2 | BG2: Threshold 2 | BH2: Spread PPS | BI2: Spread PPS Fees | BK2: CHECK | BL2: CHECK
B3: 1 | C3: SET CAP | E3: 1 | F3: SETHIA | H3: Anand | J3: IN8 | K3: 750000 | L3: 1 | M3: 750000 | N3: 22/11/2022 | O3: =L3-E3 -> 0 | P3: =O3*'IN8'!$M3 -> 0 | Q3: 0 | R3: =+'IN8'!$K3*'IN8'!$Q3 -> 0 | S3: 0 | T3: 0 | U3: 0x | AC3: 0 | AD3: =+AC3*'IN8'!$K3 -> 0 | AE3: 0 | AF3: =+AE3*'IN8'!$M3 -> 0 | AH3: 0 | AI3: =+AH3*'IN8'!$K3 -> 0 | AJ3: 0 | AK3: 0x | AN3: 0 | AO3: =+AN3*'IN8'!$M3 -> 0 | AR3: 0 | AS3: =+AR3*'IN8'!$K3 -> 0 | AT3: 0 | AU3: 0x | AX3: 0 | AY3: =+AX3*'IN8'!$M3 -> 0 | BB3: 0 | BC3: =+BB3*'IN8'!$K3 -> 0 | BD3: 0 | BE3: 0x | BH3: 0 | BI3: =+BH3*'IN8'!$M3 -> 0 | BK3: ='IN8'!$T3-AT3-BD3-AJ3 -> 0 | BL3: ='IN8'!$Q3-AH3-AR3-BB3 -> 0
B4: 2 | C4: SET CAP | E4: 1 | F4: SETHIA | H4: Anand | J4: IN8 | K4: -25000 | L4: 1 | M4: -25000 | N4: 45200 | O4: =L4-E4 -> 0 | P4: =O4*'IN8'!$M4 -> 0 | Q4: 0 | R4: =+'IN8'!$K4*'IN8'!$Q4 -> 0 | S4: 0 | T4: 0 | U4: 0x | AC4: 0 | AD4: =+AC4*'IN8'!$K4 -> 0 | AE4: 0 | AF4: =+AE4*'IN8'!$M4 -> 0 | AH4: 0 | AI4: =+AH4*'IN8'!$K4 -> 0 | AJ4: 0 | AK4: 0x | AN4: 0 | AO4: =+AN4*'IN8'!$M4 -> 0 | AR4: 0 | AS4: =+AR4*'IN8'!$K4 -> 0 | AT4: 0 | AU4: 0x | AX4: 0 | AY4: =+AX4*'IN8'!$M4 -> 0 | BB4: 0 | BC4: =+BB4*'IN8'!$K4 -> 0 | BD4: 0 | BE4: 0x | BH4: 0 | BI4: =+BH4*'IN8'!$M4 -> 0 | BK4: ='IN8'!$T4-AT4-BD4-AJ4 -> 0 | BL4: ='IN8'!$Q4-AH4-AR4-BB4 -> 0
B5: 3 | C5: SET CAP | E5: 1 | F5: SETHIA | H5: Anand | J5: IN8 | K5: -225000 | L5: 1 | M5: -225000 | N5: 44987 | O5: =L5-E5 -> 0 | P5: =O5*'IN8'!$M5 -> 0 | Q5: 0 | R5: =+'IN8'!$K5*'IN8'!$Q5 -> 0 | S5: 0 | T5: 0 | U5: 0x | AC5: 0 | AD5: =+AC5*'IN8'!$K5 -> 0 | AE5: 0 | AF5: =+AE5*'IN8'!$M5 -> 0 | AH5: 0 | AI5: =+AH5*'IN8'!$K5 -> 0 | AJ5: 0 | AK5: 0x | AN5: 0 | AO5: =+AN5*'IN8'!$M5 -> 0 | AR5: 0 | AS5: =+AR5*'IN8'!$K5 -> 0 | AT5: 0 | AU5: 0x | AX5: 0 | AY5: =+AX5*'IN8'!$M5 -> 0 | BB5: 0 | BC5: =+BB5*'IN8'!$K5 -> 0 | BD5: 0 | BE5: 0x | BH5: 0 | BI5: =+BH5*'IN8'!$M5 -> 0 | BK5: ='IN8'!$T5-AT5-BD5-AJ5 -> 0 | BL5: ='IN8'!$Q5-AH5-AR5-BB5 -> 0
B6: 4 | C6: SET CAP | E6: 1 | F6: SETHIA | H6: Anand | J6: IN8 | K6: -500000 | L6: 1 | M6: -500000 | N6: 19/04/2023 | O6: =L6-E6 -> 0 | P6: =O6*'IN8'!$M6 -> 0 | Q6: 0 | R6: =+'IN8'!$K6*'IN8'!$Q6 -> 0 | S6: 0 | T6: 0 | U6: 0x | AC6: 0 | AD6: =+AC6*'IN8'!$K6 -> 0 | AE6: 0 | AF6: =+AE6*'IN8'!$M6 -> 0 | AH6: 0 | AI6: =+AH6*'IN8'!$K6 -> 0 | AJ6: 0 | AK6: 0x | AN6: 0 | AO6: =+AN6*'IN8'!$M6 -> 0 | AR6: 0 | AS6: =+AR6*'IN8'!$K6 -> 0 | AT6: 0 | AU6: 0x | AX6: 0 | AY6: =+AX6*'IN8'!$M6 -> 0 | BB6: 0 | BC6: =+BB6*'IN8'!$K6 -> 0 | BD6: 0 | BE6: 0x | BH6: 0 | BI6: =+BH6*'IN8'!$M6 -> 0 | BK6: ='IN8'!$T6-AT6-BD6-AJ6 -> 0 | BL6: ='IN8'!$Q6-AH6-AR6-BB6 -> 0
B7: 5 | C7: SET CAP | E7: 1 | J7: IN8 | K7: 0 | L7: 1 | M7: 0 | N7: 27/01/2022 | O7: =L7-E7 -> 0 | P7: =O7*'IN8'!$M7 -> 0 | Q7: 0 | R7: =+'IN8'!$K7*'IN8'!$Q7 -> 0 | S7: 0 | T7: 0 | U7: 0x | AC7: 0 | AD7: =+AC7*'IN8'!$K7 -> 0 | AE7: 0 | AF7: =+AE7*'IN8'!$M7 -> 0 | AH7: 0 | AI7: =+AH7*'IN8'!$K7 -> 0 | AJ7: 0 | AK7: 0x | AN7: 0 | AO7: =+AN7*'IN8'!$M7 -> 0 | AR7: 0 | AS7: =+AR7*'IN8'!$K7 -> 0 | AT7: 0 | AU7: 0x | AX7: 0 | AY7: =+AX7*'IN8'!$M7 -> 0 | BB7: 0 | BC7: =+BB7*'IN8'!$K7 -> 0 | BD7: 0 | BE7: 0x | BH7: 0 | BI7: =+BH7*'IN8'!$M7 -> 0 | BK7: ='IN8'!$T7-AT7-BD7-AJ7 -> 0 | BL7: ='IN8'!$Q7-AH7-AR7-BB7 -> 0
B8: 6 | C8: SET CAP | E8: 1 | J8: IN8 | K8: 0 | L8: 1 | M8: 0 | N8: 27/01/2022 | O8: =L8-E8 -> 0 | P8: =O8*'IN8'!$M8 -> 0 | Q8: 0 | R8: =+'IN8'!$K8*'IN8'!$Q8 -> 0 | S8: 0 | T8: 0 | U8: 0x | AC8: 0 | AD8: =+AC8*'IN8'!$K8 -> 0 | AE8: 0 | AF8: =+AE8*'IN8'!$M8 -> 0 | AH8: 0 | AI8: =+AH8*'IN8'!$K8 -> 0 | AJ8: 0 | AK8: 0x | AN8: 0 | AO8: =+AN8*'IN8'!$M8 -> 0 | AR8: 0 | AS8: =+AR8*'IN8'!$K8 -> 0 | AT8: 0 | AU8: 0x | AX8: 0 | AY8: =+AX8*'IN8'!$M8 -> 0 | BB8: 0 | BC8: =+BB8*'IN8'!$K8 -> 0 | BD8: 0 | BE8: 0x | BH8: 0 | BI8: =+BH8*'IN8'!$M8 -> 0 | BK8: ='IN8'!$T8-AT8-BD8-AJ8 -> 0 | BL8: ='IN8'!$Q8-AH8-AR8-BB8 -> 0
B9: 7 | C9: SET CAP | E9: 1 | J9: IN8 | K9: 0 | L9: 1 | M9: 0 | N9: 27/01/2022 | O9: =L9-E9 -> 0 | P9: =O9*'IN8'!$M9 -> 0 | Q9: 0 | R9: =+'IN8'!$K9*'IN8'!$Q9 -> 0 | S9: 0 | T9: 0 | U9: 0x | AC9: 0 | AD9: =+AC9*'IN8'!$K9 -> 0 | AE9: 0 | AF9: =+AE9*'IN8'!$M9 -> 0 | AH9: 0 | AI9: =+AH9*'IN8'!$K9 -> 0 | AJ9: 0 | AK9: 0x | AN9: 0 | AO9: =+AN9*'IN8'!$M9 -> 0 | AR9: 0 | AS9: =+AR9*'IN8'!$K9 -> 0 | AT9: 0 | AU9: 0x | AX9: 0 | AY9: =+AX9*'IN8'!$M9 -> 0 | BB9: 0 | BC9: =+BB9*'IN8'!$K9 -> 0 | BD9: 0 | BE9: 0x | BH9: 0 | BI9: =+BH9*'IN8'!$M9 -> 0 | BK9: ='IN8'!$T9-AT9-BD9-AJ9 -> 0 | BL9: ='IN8'!$Q9-AH9-AR9-BB9 -> 0
B10: 8 | C10: SET CAP | E10: 1 | J10: IN8 | K10: 0 | L10: 1 | M10: 0 | N10: 24/02/2022 | O10: =L10-E10 -> 0 | P10: =O10*'IN8'!$M10 -> 0 | Q10: 0 | R10: =+'IN8'!$K10*'IN8'!$Q10 -> 0 | S10: 0 | T10: 0 | U10: 0x | AC10: 0 | AD10: =+AC10*'IN8'!$K10 -> 0 | AE10: 0 | AF10: =+AE10*'IN8'!$M10 -> 0 | AH10: 0 | AI10: =+AH10*'IN8'!$K10 -> 0 | AJ10: 0 | AK10: 0x | AN10: 0 | AO10: =+AN10*'IN8'!$M10 -> 0 | AR10: 0 | AS10: =+AR10*'IN8'!$K10 -> 0 | AT10: 0 | AU10: 0x | AX10: 0 | AY10: =+AX10*'IN8'!$M10 -> 0 | BB10: 0 | BC10: =+BB10*'IN8'!$K10 -> 0 | BD10: 0 | BE10: 0x | BH10: 0 | BI10: =+BH10*'IN8'!$M10 -> 0 | BK10: ='IN8'!$T10-AT10-BD10-AJ10 -> 0 | BL10: ='IN8'!$Q10-AH10-AR10-BB10 -> 0
B11: 9 | C11: SET CAP | E11: 1 | J11: IN8 | K11: 0 | L11: 1 | M11: 0 | N11: 27/01/2022 | O11: =L11-E11 -> 0 | P11: =O11*'IN8'!$M11 -> 0 | Q11: 0 | R11: =+'IN8'!$K11*'IN8'!$Q11 -> 0 | S11: 0 | T11: 0 | U11: 0x | AC11: 0 | AD11: =+AC11*'IN8'!$K11 -> 0 | AE11: 0 | AF11: =+AE11*'IN8'!$M11 -> 0 | AH11: 0 | AI11: =+AH11*'IN8'!$K11 -> 0 | AJ11: 0 | AK11: 0x | AN11: 0 | AO11: =+AN11*'IN8'!$M11 -> 0 | AR11: 0 | AS11: =+AR11*'IN8'!$K11 -> 0 | AT11: 0 | AU11: 0x | AX11: 0 | AY11: =+AX11*'IN8'!$M11 -> 0 | BB11: 0 | BC11: =+BB11*'IN8'!$K11 -> 0 | BD11: 0 | BE11: 0x | BH11: 0 | BI11: =+BH11*'IN8'!$M11 -> 0 | BK11: ='IN8'!$T11-AT11-BD11-AJ11 -> 0 | BL11: ='IN8'!$Q11-AH11-AR11-BB11 -> 0
C12: Total | K12: =SUBTOTAL(109,'IN8'!$K$3:$K$11) -> 0 | M12: =SUBTOTAL(109,'IN8'!$M$3:$M$11) -> 0 | P12: =SUBTOTAL(109,'IN8'!$P$3:$P$11) -> 0 | R12: =SUBTOTAL(109,'IN8'!$R$3:$R$11) -> 0
K14: =+(P14+R14)/'IN8'!$K$12 -> #DIV/0! | P14: =+SUM('IN8'!$P$3:$P$11)-SUM(AY3:AY11)-SUM(BI3:BJ11) -> 0 | R14: =+SUM('IN8'!$R$3:$R$11)-SUM(AS3:AS11)-SUM(BC3:BC11)-SUM(AD3:AD11) -> 0 | T14: =SUMPRODUCT(T3:T11,K3:K11)/SUM(K3:K11) -> #DIV/0!
P15: =+P14/'IN8'!$P$12 -> #DIV/0! | R15: =+R14/'IN8'!$R$12 -> #DIV/0!

Sheet IN9
AH1: VERSO CAPITAL | AR1: PARTNERS excluding JM | BB1: INTRODUCERS | BK1: JM
B2: Index | C2: Opportunity | D2: Sourcing Contract ref | E2: Cost per Share | F2: Investor Last Name | G2: Investor Middle Name | H2: Investor First Name | I2: Investor Entity | J2: Vehicle | K2: Amount invested | L2: Price per Share | M2: Number of shares invested | N2: Contract Date | O2: Spread PPS | P2: Spread PPS Fees | Q2: Subscription fees % | R2: Subscription fees | S2: Management Fee | T2: Performance fees 1 | U2: Threshold 1 | V2: Performance fees 2 | W2: Threshold 2 | X2: Comments | Y2: TO DO | AC2: BD Fees % | AD2: BD fees | AE2: FINRA fees in share | AF2: FINRA fees | AH2: Subscription fees % | AI2: Subscription fees | AJ2: Performance fees 1 | AK2: Threshold 1 | AL2: Performance fees 2 | AM2: Threshold 2 | AN2: Spread PPS | AO2: Spread PPS Fees | AQ2: Name | AR2: Subscription fees % | AS2: Subscription fees | AT2: Performance fees 1 | AU2: Threshold 1 | AV2: Performance fees 2 | AW2: Threshold 2 | AX2: Spread PPS | AY2: Spread PPS Fees | BA2: Name | BB2: Subscription fees % | BC2: Subscription fees | BD2: Performance fees 1 | BE2: Threshold 1 | BF2: Performance fees 2 | BG2: Threshold 2 | BH2: Spread PPS | BI2: Spread PPS Fees | BK2: CHECK | BL2: CHECK
B3: 1 | C3: SC TBC INVEST 3 | E3: 98 | I3: L1 SC Invest 6 | J3: IN9 | K3: 595000 | L3: 98 | M3: 6071 | N3: 21/12/2022 | O3: =L3-E3 -> 0 | P3: =O3*'IN9'!$M3 -> 0 | Q3: 0 | R3: =+'IN9'!$K3*'IN9'!$Q3 -> 0 | S3: 0.02 | T3: 0 | U3: 0x | X3: 2.00% pa compounded in Redemption Calculations | AC3: 0 | AD3: =+AC3*'IN9'!$K3 -> 0 | AE3: 0 | AF3: =+AE3*'IN9'!$M3 -> 0 | AH3: 0 | AI3: =+AH3*'IN9'!$K3 -> 0 | AJ3: 0 | AK3: 0x | AN3: 0 | AO3: =+AN3*'IN9'!$M3 -> 0 | AR3: 0 | AS3: =+AR3*'IN9'!$K3 -> 0 | AT3: 0 | AU3: 0x | AX3: 0 | AY3: =+AX3*'IN9'!$M3 -> 0 | BB3: 0 | BC3: =+BB3*'IN9'!$K3 -> 0 | BD3: 0 | BE3: 0x | BH3: 0 | BI3: =+BH3*'IN9'!$M3 -> 0 | BK3: ='IN9'!$T3-AT3-BD3-AJ3 -> 0 | BL3: ='IN9'!$Q3-AH3-AR3-BB3 -> 0
